Workbook

Sheet Portada
B8: Memoria de cálculo de la capacidad portante admisible
B9: Objetivo específico 3 · Actividad 4 — Formulación de Meyerhof bajo el Título H de la NSR-10
B11: Objetivo | C11: OE 3: Estimar la capacidad portante preliminar del terreno de fundación de las infraestructuras de superficie en los portales de Ibagué y Armenia
B12: Actividad | C12: 4. Cálculo de la capacidad portante admisible por la formulación de Meyerhof (NSR-10, Título H)
B13: Entregable / formato | C13: Memoria de cálculo · Documento Excel
B14: Periodo | C14: Bloque 2 del Plan de Acción (5 oct - 7 nov 2026)
B15: Responsable asignado | C15: Tamayo Osorio Miguel Ángel
B16: Semillero | C16: Semillero de Investigación GEOPAV · Ingeniería Civil · Universidad de Ibagué · Paz y Región 2026B
B17: Portales | C17: Oriental (Ibagué) sobre suelo S1 · Occidental (municipio de Calarcá) sobre suelo S2
B18: Fecha de elaboración | C18: 28 sep 2026
B19: Advertencia | C19: RESULTADO NO APTO PARA DISEÑO. Ningún parámetro proviene de exploración en los portales: son análogos publicados e hipótesis declaradas (Act 3). La capacidad admisible se entrega como RANGO para mostrar la sensibilidad y dimensionar la exploración que exige la NSR-10 (capítulo H.3) antes de cualquier diseño.
B21: Índice de hojas (tabla de contenido)
B22: Resumen | C22: Tabla 1. Capacidad admisible por portal y ancho de zapata (rango, FS 3,0)
B23: Entradas | C23: Tabla 2. Parámetros del suelo (desde la Act 3) · Tabla 3. Hipótesis de cálculo · Tabla 4. Factores de seguridad NSR-10
B24: Cálculo | C24: Tabla 5. Meyerhof: factores, capacidad última, admisible por falla y por asentamiento (36 casos)
B25: Chequeo H.2.4-1 | C25: Tabla 6. Factor de seguridad directo equivalente frente a la tabla H.2.4-1
B26: Verificación | C26: Tabla 7. Control de los factores Nc, Nq, Nγ contra la tabla 4-4 de EM 1110-1-1905
B27: Limitaciones | C27: Tabla 8. Qué no afirma esta memoria · Tabla 9. Exploración mínima para convertir el rango en diseño
B28: Marcas y fuentes | C28: Tabla 10. Marcas F / CP / H · Tabla 11. Fuentes citadas
B30: Índice de tablas: tablas 1 a 11, una o dos por hoja, según el índice de hojas. Índice de figuras: no tiene figuras. Índice de anexos: no tiene anexos; las fuentes descargadas se listan en la tabla 11. Convención: texto azul = entrada editable; texto verde = valor enlazado desde otra hoja; fondo amarillo = hipótesis [H]; fondo verde = resultado. Elaborado con apoyo de IA (Claude) y verificado contra las fuentes citadas, leídas en el original descargado. Script: OE3_Geotecnia/Act4_Capacidad/memoria_capacidad_portante_OE3.py

Sheet Resumen
A1: Tabla 1. Capacidad portante admisible por portal y ancho de zapata — CM + CV normal (FS 3,0), NSR-10 H.4.2.3
A2: Rango, no valor de diseño. Mínimo: parámetros mínimos y NF en la base. Máximo: parámetros máximos y NF profundo. Df = 1,5 m. Valores en kPa, desde la hoja «Cálculo».
A4: Portal | B4: Suelo | C4: B (m) | D4: Mínimo | E4: Típico, NF en la base | F4: Típico, NF profundo | G4: Máximo | H4: Gobierna en el típico con NF profundo | I4: qult típico, NF profundo
A5: Oriental (Ibagué) | B5: S1 · suelo residual sobre PCAn / Jcdi (análogo del Batolito Antioqueño) | C5: 1.5 | D5: =Cálculo!Y5 -> 60.182723 | E5: =Cálculo!Y11 -> 224.50498 | F5: =Cálculo!Y12 -> 224.50498 | G5: =Cálculo!Y18 -> 388.82723 | H5: =Cálculo!Z12 -> Asentamiento | I5: =Cálculo!S12 -> 1994.2578
A6: Oriental (Ibagué) | B6: S1 · suelo residual sobre PCAn / Jcdi (análogo del Batolito Antioqueño) | C6: 2 | D6: =Cálculo!Y7 -> 51.137042 | E6: =Cálculo!Y13 -> 174.75373 | F6: =Cálculo!Y14 -> 174.75373 | G6: =Cálculo!Y20 -> 298.37042 | H6: =Cálculo!Z14 -> Asentamiento | I6: =Cálculo!S14 -> 1991.766
A7: Oriental (Ibagué) | B7: S1 · suelo residual sobre PCAn / Jcdi (análogo del Batolito Antioqueño) | C7: 3 | D7: =Cálculo!Y9 -> 42.091361 | E7: =Cálculo!Y15 -> 125.00249 | F7: =Cálculo!Y16 -> 125.00249 | G7: =Cálculo!Y22 -> 207.91361 | H7: =Cálculo!Z16 -> Asentamiento | I7: =Cálculo!S16 -> 2075.8402
A8: Occidental (Calarcá) | B8: S2 · cobertura de cenizas alofánicas sobre Kqs / Kqv (análogo de Pereira) | C8: 1.5 | D8: =Cálculo!Y23 -> 68.386715 | E8: =Cálculo!Y29 -> 197.1285 | F8: =Cálculo!Y30 -> 197.1285 | G8: =Cálculo!Y36 -> 326.62029 | H8: =Cálculo!Z30 -> Asentamiento | I8: =Cálculo!S30 -> 1948.848
A9: Occidental (Calarcá) | B9: S2 · cobertura de cenizas alofánicas sobre Kqs / Kqv (análogo de Pereira) | C9: 2 | D9: =Cálculo!Y25 -> 55.752536 | E9: =Cálculo!Y31 -> 152.90888 | F9: =Cálculo!Y32 -> 152.90888 | G9: =Cálculo!Y38 -> 250.81522 | H9: =Cálculo!Z32 -> Asentamiento | I9: =Cálculo!S32 -> 1897.8193
A10: Occidental (Calarcá) | B10: S2 · cobertura de cenizas alofánicas sobre Kqs / Kqv (análogo de Pereira) | C10: 3 | D10: =Cálculo!Y27 -> 43.118358 | E10: =Cálculo!Y33 -> 108.68925 | F10: =Cálculo!Y34 -> 108.68925 | G10: =Cálculo!Y40 -> 175.01015 | H10: =Cálculo!Z34 -> Asentamiento | I10: =Cálculo!S34 -> 1895.016
A12: Cómo leerlo: la amplitud entre «Mínimo» y «Máximo» mide la incertidumbre de los parámetros análogos. Solo la exploración del capítulo H.3 (hoja «Limitaciones») permite cerrarla.
A13: Donde gobierna el asentamiento, aumentar B no aumenta la admisible: el límite lo pone el módulo E [H], no la resistencia al corte.
A14: Fuente: hoja «Cálculo» (Tabla 5). Marcas: resultados [CP]; entradas F y H según la Tabla 2.

Sheet Entradas
A1: Tabla 2. Parámetros del suelo de fundación (leídos del producto de la Act 3) y módulo de deformación
A2: c, φ y γ: copiados por el script desde Cuadro_parametros_adoptados_OE3.xlsx (hoja «Suelos»); no se editan aquí. E y ν: FHWA NHI-06-088, tabla 5-16.
A4: Juego | B4: Portal | C4: Parámetro | D4: Unidad | E4: Mínimo | F4: Típico | G4: Máximo | H4: Marca | I4: Origen
A5: S1 | B5: Oriental (Ibagué) | C5: c′ (cohesión efectiva) | D5: kPa | E5: 0 | F5: 15 | G5: 29 | H5: F | I5: Act 3, hoja Suelos, fila 5 (fuente CAR74)
A6: S1 | B6: Oriental (Ibagué) | C6: φ′ (ángulo de fricción efectivo) | D6: ° | E6: 27 | F6: 30 | G6: 32 | H6: F | I6: Act 3, hoja Suelos, fila 6 (fuente CAR74)
A7: S1 | B7: Oriental (Ibagué) | C7: γ (peso unitario total) | D7: kN/m³ | E7: 16 | F7: 17 | G7: 18 | H7: H | I7: Act 3, hoja Suelos, fila 7 (fuente —)
A8: S1 | B8: Oriental (Ibagué) | C8: E (módulo de Young, drenado equivalente) | D8: kPa | E8: =20*$C$23 -> 1915.2 | F8: =110*$C$23 -> 10533.6 | G8: =200*$C$23 -> 19152 | H8: F / H | I8: FHWA 088 tabla 5-16, Limo arenoso residual → fila «Silt» 20-200 tsf [H: asignación]. Típico = punto medio [H].
A9: S1 | B9: Oriental (Ibagué) | C9: ν (relación de Poisson) | D9: — | E9: 0.33 | F9: 0.33 | G9: 0.33 | H9: F / H | I9: FHWA 088 tabla 5-16: 0,30-0,35; se adopta un valor único [H].
A10: S2 | B10: Occidental (Calarcá) | C10: c (cohesión, ensayo UU) | D10: kPa | E10: 15 | F10: 25 | G10: 35 | H10: F | I10: Act 3, hoja Suelos, fila 8 (fuente BBM13)
A11: S2 | B11: Occidental (Calarcá) | C11: φ (ángulo de fricción, UU) | D11: ° | E11: 23 | F11: 28 | G11: 33 | H11: F | I11: Act 3, hoja Suelos, fila 9 (fuente BBM13)
A12: S2 | B12: Occidental (Calarcá) | C12: γ (peso unitario húmedo) | D12: kN/m³ | E12: 11.9 | F12: 13.5 | G12: 15.6 | H12: F | I12: Act 3, hoja Suelos, fila 10 (fuente BBM13)
A13: S2 | B13: Occidental (Calarcá) | C13: E (módulo de Young, drenado equivalente) | D13: kPa | E13: =25*$C$23 -> 2394 | F13: =87.5*$C$23 -> 8379 | G13: =150*$C$23 -> 14364 | H13: F / H | I13: FHWA 088 tabla 5-16, Ceniza alofánica CL-SC, sensible al saturarse → fila «Clay: soft sensitive» 25-150 tsf [H: asignación]. Típico = punto medio [H].
A14: S2 | B14: Occidental (Calarcá) | C14: ν (relación de Poisson) | D14: — | E14: 0.45 | F14: 0.45 | G14: 0.45 | H14: F / H | I14: FHWA 088 tabla 5-16: 0,4-0,5 (no drenado); se adopta un valor único [H].
A16: Tabla 3. Hipótesis de cálculo
A17: # | B17: Hipótesis | C17: Valor | D17: Unidad | E17: Marca | F17: Justificación
A18: 1 | B18: Df, profundidad de desplante | C18: 1.5 | D18: m | E18: H | F18: Zapata aislada típica de nave o marquesina de terminal; la fuente no trae estructuras de las terminales Ro-Ro.
A19: 2 | B19: γw, peso unitario del agua | C19: 9.81 | D19: kN/m³ | E19: F | F19: Constante física.
A20: 3 | B20: ρadm, asentamiento admisible | C20: 0.025 | D20: m | E20: H | F20: Conservador frente a NSR-10 H.4.9: si el diferencial ≈ total (portales sobre contactos litológicos), 25 mm ≈ A/300 con A = 7,5 m (pórticos de concreto, tabla H.4.9-1). Límite total NSR-10 H.4.9.2: 300 mm.
A21: 4 | B21: Cd, factor de forma y rigidez | C21: 0.99 | D21: — | E21: F | F21: FHWA 089 tabla 8-13, cuadrada rígida (0,99).
A22: 5 | B22: B'/W', relación ancho/largo | C22: 1 | D22: — | E22: H | F22: Zapata cuadrada, carga centrada (sin excentricidad ni inclinación).
A23: 6 | B23: 1 tsf en kPa | C23: 95.76 | D23: kPa | E23: F | F23: FHWA 088, nota de la tabla 5-16.
A25: Tabla 4. Factores de seguridad del Título H de la NSR-10 (verificados en el texto de la norma)
A26: # | B26: Condición | C26: FSICP mín. (tabla H.4.7-1) | D26: FSBM mín. diseño (tabla H.2.4-1) | E26: Marca
A27: 1 | B27: CM + CV normal | C27: 3 | D27: 1.5 | E27: F
A28: 2 | B28: CM + CV máxima | C28: 2.5 | D28: 1.25 | E28: F
A29: 3 | B29: CM + CV normal + sismo seudoestático | C29: 1.5 | D29: 1.1 | E29: F
A31: Fuente: NSR-10 Título H, H.4.7.1 (tabla H.4.7-1) y H.2.4.3 (tabla H.2.4-1). La NSR-10 no impone Meyerhof: H.4.2.1 admite métodos analíticos con experiencia documentada.

Sheet Cálculo
A1: Tabla 5. Capacidad portante por Meyerhof (1963) y admisible según NSR-10 H.4.2.3 — zapatas cuadradas, carga vertical centrada
A2: qult = c·Nc·sc·dc + q·Nq·sq·dq + ½·γ'·B·Nγ·sγ·dγ (EM 1110-1-1905 ec. 4-1 y tabla 4-3). q = γ·Df. γ' = γ − γw con NF en la base; γ' = γ con NF profundo. Asentamiento: ρ = Cd·Δp·B·(1−ν²)/E (FHWA 089 ec. 8-19) → q_s = ρadm·E/(Cd·B·(1−ν²)) + γ·Df. Todo [CP].
AD3: Columnas auxiliares: resistencia reducida por el FSBM de la tabla H.2.4-1 (c/FSBM y arctan(tanφ/FSBM))
A4: Juego | B4: Portal | C4: Caso | D4: B (m) | E4: Nivel freático | F4: c (kPa) | G4: φ (°) | H4: γ (kN/m³) | I4: γ' bajo la base | J4: q = γ·Df (kPa) | K4: Nφ = tan²(45+φ/2) | L4: Nq | M4: Nc | N4: Nγ | O4: sc | P4: sq = sγ | Q4: dc | R4: dq = dγ | S4: qult (kPa) | T4: qult / FSICP 3,0 (kPa) | U4: qult con resistencia ÷ FSBM 1,50 (kPa) | V4: qadm por falla (kPa) | W4: E (kPa) | X4: q por asentamiento (kPa) | Y4: qadm NSR-10 H.4.2.3 (kPa) | Z4: Gobierna | AA4: qadm falla CM+CV máx. (kPa) | AB4: qadm falla con sismo (kPa) | AD4: φ/FSB 1,50 (°) | AE4: Nφ (1,50) | AF4: Nq (1,50) | AG4: Nc (1,50) | AH4: Nγ (1,50) | AI4: qult reducida 1,50 (kPa) | AJ4: φ/FSB 1,25 (°) | AK4: Nφ (1,25) | AL4: Nq (1,25) | AM4: Nc (1,25) | AN4: Nγ (1,25) | AO4: qult reducida 1,25 (kPa) | AP4: φ/FSB 1,10 (°) | AQ4: Nφ (1,10) | AR4: Nq (1,10) | AS4: Nc (1,10) | AT4: Nγ (1,10) | AU4: qult reducida 1,10 (kPa)
A5: S1 | B5: Oriental (Ibagué) | C5: Mínimo | D5: 1.5 | E5: NF en la base | F5: =Entradas!E5 -> 0 | G5: =Entradas!E6 -> 27 | H5: =Entradas!E7 -> 16 | I5: =IF(E5="NF en la base",H5-Entradas!$C$19,H5) -> 6.19 | J5: =H5*Entradas!$C$18 -> 24 | K5: =TAN(RADIANS(45+G5/2))^2 -> 2.6629399 | L5: =EXP(PI()*TAN(RADIANS(G5)))*K5 -> 13.199146 | M5: =(L5-1)/TAN(RADIANS(G5)) -> 23.942173 | N5: =(L5-1)*TAN(RADIANS(1.4*G5)) -> 9.4626279 | O5: =1+0.2*K5*Entradas!$C$22 -> 1.532588 | P5: =1+0.1*K5*Entradas!$C$22 -> 1.266294 | Q5: =1+0.2*SQRT(K5)*Entradas!$C$18/D5 -> 1.3263703 | R5: =1+0.1*SQRT(K5)*Entradas!$C$18/D5 -> 1.1631852 | S5: =F5*M5*O5*Q5+J5*L5*P5*R5+0.5*I5*D5*N5*P5*R5 -> 531.30181 | T5: =S5/Entradas!$C$27 -> 177.1006 | U5: =AI5 -> 199.63091 | V5: =MIN(T5,U5) -> 177.1006 | W5: =Entradas!E8 -> 1915.2 | X5: =Entradas!$C$20*W5/(Entradas!$C$21*D5*(1-Entradas!E9^2))+J5 -> 60.182723 | Y5: =MIN(V5,X5) -> 60.182723 | Z5: =IF(X5<V5,"Asentamiento",IF(T5<=U5,"Falla (FSICP)","Falla (FSB directo)")) -> Asentamiento | AA5: =MIN(S5/Entradas!$C$28,AO5) -> 212.52073 | AB5: =MIN(S5/Entradas!$C$29,AU5) -> 354.20121 | AD5: =DEGREES(ATAN(TAN(RADIANS(G5))/Entradas!$D$27)) -> 18.761783 | AE5: =TAN(RADIANS(45+AD5/2))^2 -> 1.9482619 | AF5: =EXP(PI()*TAN(RADIANS(AD5)))*AE5 -> 5.6637444 | AG5: =(AF5-1)/TAN(RADIANS(AD5)) -> 13.729671 | AH5: =(AF5-1)*TAN(RADIANS(1.4*AD5)) -> 2.3015738 | AI5: =F5/Entradas!$D$27*AG5*(1+0.2*AE5*Entradas!$C$22)*(1+0.2*SQRT(AE5)*Entradas!$C$18/D5)+J5*AF5*(1+0.1*AE5*Entradas!$C$22)*(1+0.1*SQRT(AE5)*Entradas!$C$18/D5)+0.5*I5*D5*AH5*(1+0.1*AE5*Entradas!$C$22)*(1+0.1*SQRT(AE5)*Entradas!$C$18/D5) -> 199.63091 | AJ5: =DEGREES(ATAN(TAN(RADIANS(G5))/Entradas!$D$28)) -> 22.176809 | AK5: =TAN(RADIANS(45+AJ5/2))^2 -> 2.212676 | AL5: =EXP(PI()*TAN(RADIANS(AJ5)))*AK5 -> 7.9627925 | AM5: =(AL5-1)/TAN(RADIANS(AJ5)) -> 17.081562 | AN5: =(AL5-1)*TAN(RADIANS(1.4*AJ5)) -> 4.1915336 | AO5: =F5/Entradas!$D$28*AM5*(1+0.2*AK5*Entradas!$C$22)*(1+0.2*SQRT(AK5)*Entradas!$C$18/D5)+J5*AL5*(1+0.1*AK5*Entradas!$C$22)*(1+0.1*SQRT(AK5)*Entradas!$C$18/D5)+0.5*I5*D5*AN5*(1+0.1*AK5*Entradas!$C$22)*(1+0.1*SQRT(AK5)*Entradas!$C$18/D5) -> 295.41007 | AP5: =DEGREES(ATAN(TAN(RADIANS(G5))/Entradas!$D$29)) -> 24.853806 | AQ5: =TAN(RADIANS(45+AP5/2))^2 -> 2.4500865 | AR5: =EXP(PI()*TAN(RADIANS(AP5)))*AQ5 -> 10.499468 | AS5: =(AR5-1)/TAN(RADIANS(AP5)) -> 20.508131 | AT5: =(AR5-1)*TAN(RADIANS(1.4*AP5)) -> 6.6011536 | AU5: =F5/Entradas!$D$29*AS5*(1+0.2*AQ5*Entradas!$C$22)*(1+0.2*SQRT(AQ5)*Entradas!$C$18/D5)+J5*AR5*(1+0.1*AQ5*Entradas!$C$22)*(1+0.1*SQRT(AQ5)*Entradas!$C$18/D5)+0.5*I5*D5*AT5*(1+0.1*AQ5*Entradas!$C$22)*(1+0.1*SQRT(AQ5)*Entradas!$C$18/D5) -> 406.95964
A6: S1 | B6: Oriental (Ibagué) | C6: Mínimo | D6: 1.5 | E6: NF profundo | F6: =Entradas!E5 -> 0 | G6: =Entradas!E6 -> 27 | H6: =Entradas!E7 -> 16 | I6: =IF(E6="NF en la base",H6-Entradas!$C$19,H6) -> 16 | J6: =H6*Entradas!$C$18 -> 24 | K6: =TAN(RADIANS(45+G6/2))^2 -> 2.6629399 | L6: =EXP(PI()*TAN(RADIANS(G6)))*K6 -> 13.199146 | M6: =(L6-1)/TAN(RADIANS(G6)) -> 23.942173 | N6: =(L6-1)*TAN(RADIANS(1.4*G6)) -> 9.4626279 | O6: =1+0.2*K6*Entradas!$C$22 -> 1.532588 | P6: =1+0.1*K6*Entradas!$C$22 -> 1.266294 | Q6: =1+0.2*SQRT(K6)*Entradas!$C$18/D6 -> 1.3263703 | R6: =1+0.1*SQRT(K6)*Entradas!$C$18/D6 -> 1.1631852 | S6: =F6*M6*O6*Q6+J6*L6*P6*R6+0.5*I6*D6*N6*P6*R6 -> 633.8494 | T6: =S6/Entradas!$C$27 -> 211.28313 | U6: =AI6 -> 222.68801 | V6: =MIN(T6,U6) -> 211.28313 | W6: =Entradas!E8 -> 1915.2 | X6: =Entradas!$C$20*W6/(Entradas!$C$21*D6*(1-Entradas!E9^2))+J6 -> 60.182723 | Y6: =MIN(V6,X6) -> 60.182723 | Z6: =IF(X6<V6,"Asentamiento",IF(T6<=U6,"Falla (FSICP)","Falla (FSB directo)")) -> Asentamiento | AA6: =MIN(S6/Entradas!$C$28,AO6) -> 253.53976 | AB6: =MIN(S6/Entradas!$C$29,AU6) -> 422.56627 | AD6: =DEGREES(ATAN(TAN(RADIANS(G6))/Entradas!$D$27)) -> 18.761783 | AE6: =TAN(RADIANS(45+AD6/2))^2 -> 1.9482619 | AF6: =EXP(PI()*TAN(RADIANS(AD6)))*AE6 -> 5.6637444 | AG6: =(AF6-1)/TAN(RADIANS(AD6)) -> 13.729671 | AH6: =(AF6-1)*TAN(RADIANS(1.4*AD6)) -> 2.3015738 | AI6: =F6/Entradas!$D$27*AG6*(1+0.2*AE6*Entradas!$C$22)*(1+0.2*SQRT(AE6)*Entradas!$C$18/D6)+J6*AF6*(1+0.1*AE6*Entradas!$C$22)*(1+0.1*SQRT(AE6)*Entradas!$C$18/D6)+0.5*I6*D6*AH6*(1+0.1*AE6*Entradas!$C$22)*(1+0.1*SQRT(AE6)*Entradas!$C$18/D6) -> 222.68801 | AJ6: =DEGREES(ATAN(TAN(RADIANS(G6))/Entradas!$D$28)) -> 22.176809 | AK6: =TAN(RADIANS(45+AJ6/2))^2 -> 2.212676 | AL6: =EXP(PI()*TAN(RADIANS(AJ6)))*AK6 -> 7.9627925 | AM6: =(AL6-1)/TAN(RADIANS(AJ6)) -> 17.081562 | AN6: =(AL6-1)*TAN(RADIANS(1.4*AJ6)) -> 4.1915336 | AO6: =F6/Entradas!$D$28*AM6*(1+0.2*AK6*Entradas!$C$22)*(1+0.2*SQRT(AK6)*Entradas!$C$18/D6)+J6*AL6*(1+0.1*AK6*Entradas!$C$22)*(1+0.1*SQRT(AK6)*Entradas!$C$18/D6)+0.5*I6*D6*AN6*(1+0.1*AK6*Entradas!$C$22)*(1+0.1*SQRT(AK6)*Entradas!$C$18/D6) -> 338.67539 | AP6: =DEGREES(ATAN(TAN(RADIANS(G6))/Entradas!$D$29)) -> 24.853806 | AQ6: =TAN(RADIANS(45+AP6/2))^2 -> 2.4500865 | AR6: =EXP(PI()*TAN(RADIANS(AP6)))*AQ6 -> 10.499468 | AS6: =(AR6-1)/TAN(RADIANS(AP6)) -> 20.508131 | AT6: =(AR6-1)*TAN(RADIANS(1.4*AP6)) -> 6.6011536 | AU6: =F6/Entradas!$D$29*AS6*(1+0.2*AQ6*Entradas!$C$22)*(1+0.2*SQRT(AQ6)*Entradas!$C$18/D6)+J6*AR6*(1+0.1*AQ6*Entradas!$C$22)*(1+0.1*SQRT(AQ6)*Entradas!$C$18/D6)+0.5*I6*D6*AT6*(1+0.1*AQ6*Entradas!$C$22)*(1+0.1*SQRT(AQ6)*Entradas!$C$18/D6) -> 476.89205
A7: S1 | B7: Oriental (Ibagué) | C7: Mínimo | D7: 2 | E7: NF en la base | F7: =Entradas!E5 -> 0 | G7: =Entradas!E6 -> 27 | H7: =Entradas!E7 -> 16 | I7: =IF(E7="NF en la base",H7-Entradas!$C$19,H7) -> 6.19 | J7: =H7*Entradas!$C$18 -> 24 | K7: =TAN(RADIANS(45+G7/2))^2 -> 2.6629399 | L7: =EXP(PI()*TAN(RADIANS(G7)))*K7 -> 13.199146 | M7: =(L7-1)/TAN(RADIANS(G7)) -> 23.942173 | N7: =(L7-1)*TAN(RADIANS(1.4*G7)) -> 9.4626279 | O7: =1+0.2*K7*Entradas!$C$22 -> 1.532588 | P7: =1+0.1*K7*Entradas!$C$22 -> 1.266294 | Q7: =1+0.2*SQRT(K7)*Entradas!$C$18/D7 -> 1.2447778 | R7: =1+0.1*SQRT(K7)*Entradas!$C$18/D7 -> 1.1223889 | S7: =F7*M7*O7*Q7+J7*L7*P7*R7+0.5*I7*D7*N7*P7*R7 -> 533.47982 | T7: =S7/Entradas!$C$27 -> 177.82661 | U7: =AI7 -> 198.21911 | V7: =MIN(T7,U7) -> 177.82661 | W7: =Entradas!E8 -> 1915.2 | X7: =Entradas!$C$20*W7/(Entradas!$C$21*D7*(1-Entradas!E9^2))+J7 -> 51.137042 | Y7: =MIN(V7,X7) -> 51.137042 | Z7: =IF(X7<V7,"Asentamiento",IF(T7<=U7,"Falla (FSICP)","Falla (FSB directo)")) -> Asentamiento | AA7: =MIN(S7/Entradas!$C$28,AO7) -> 213.39193 | AB7: =MIN(S7/Entradas!$C$29,AU7) -> 355.65322 | AD7: =DEGREES(ATAN(TAN(RADIANS(G7))/Entradas!$D$27)) -> 18.761783 | AE7: =TAN(RADIANS(45+AD7/2))^2 -> 1.9482619 | AF7: =EXP(PI()*TAN(RADIANS(AD7)))*AE7 -> 5.6637444 | AG7: =(AF7-1)/TAN(RADIANS(AD7)) -> 13.729671 | AH7: =(AF7-1)*TAN(RADIANS(1.4*AD7)) -> 2.3015738 | AI7: =F7/Entradas!$D$27*AG7*(1+0.2*AE7*Entradas!$C$22)*(1+0.2*SQRT(AE7)*Entradas!$C$18/D7)+J7*AF7*(1+0.1*AE7*Entradas!$C$22)*(1+0.1*SQRT(AE7)*Entradas!$C$18/D7)+0.5*I7*D7*AH7*(1+0.1*AE7*Entradas!$C$22)*(1+0.1*SQRT(AE7)*Entradas!$C$18/D7) -> 198.21911 | AJ7: =DEGREES(ATAN(TAN(RADIANS(G7))/Entradas!$D$28)) -> 22.176809 | AK7: =TAN(RADIANS(45+AJ7/2))^2 -> 2.212676 | AL7: =EXP(PI()*TAN(RADIANS(AJ7)))*AK7 -> 7.9627925 | AM7: =(AL7-1)/TAN(RADIANS(AJ7)) -> 17.081562 | AN7: =(AL7-1)*TAN(RADIANS(1.4*AJ7)) -> 4.1915336 | AO7: =F7/Entradas!$D$28*AM7*(1+0.2*AK7*Entradas!$C$22)*(1+0.2*SQRT(AK7)*Entradas!$C$18/D7)+J7*AL7*(1+0.1*AK7*Entradas!$C$22)*(1+0.1*SQRT(AK7)*Entradas!$C$18/D7)+0.5*I7*D7*AN7*(1+0.1*AK7*Entradas!$C$22)*(1+0.1*SQRT(AK7)*Entradas!$C$18/D7) -> 294.65237 | AP7: =DEGREES(ATAN(TAN(RADIANS(G7))/Entradas!$D$29)) -> 24.853806 | AQ7: =TAN(RADIANS(45+AP7/2))^2 -> 2.4500865 | AR7: =EXP(PI()*TAN(RADIANS(AP7)))*AQ7 -> 10.499468 | AS7: =(AR7-1)/TAN(RADIANS(AP7)) -> 20.508131 | AT7: =(AR7-1)*TAN(RADIANS(1.4*AP7)) -> 6.6011536 | AU7: =F7/Entradas!$D$29*AS7*(1+0.2*AQ7*Entradas!$C$22)*(1+0.2*SQRT(AQ7)*Entradas!$C$18/D7)+J7*AR7*(1+0.1*AQ7*Entradas!$C$22)*(1+0.1*SQRT(AQ7)*Entradas!$C$18/D7)+0.5*I7*D7*AT7*(1+0.1*AQ7*Entradas!$C$22)*(1+0.1*SQRT(AQ7)*Entradas!$C$18/D7) -> 407.40106
A8: S1 | B8: Oriental (Ibagué) | C8: Mínimo | D8: 2 | E8: NF profundo | F8: =Entradas!E5 -> 0 | G8: =Entradas!E6 -> 27 | H8: =Entradas!E7 -> 16 | I8: =IF(E8="NF en la base",H8-Entradas!$C$19,H8) -> 16 | J8: =H8*Entradas!$C$18 -> 24 | K8: =TAN(RADIANS(45+G8/2))^2 -> 2.6629399 | L8: =EXP(PI()*TAN(RADIANS(G8)))*K8 -> 13.199146 | M8: =(L8-1)/TAN(RADIANS(G8)) -> 23.942173 | N8: =(L8-1)*TAN(RADIANS(1.4*G8)) -> 9.4626279 | O8: =1+0.2*K8*Entradas!$C$22 -> 1.532588 | P8: =1+0.1*K8*Entradas!$C$22 -> 1.266294 | Q8: =1+0.2*SQRT(K8)*Entradas!$C$18/D8 -> 1.2447778 | R8: =1+0.1*SQRT(K8)*Entradas!$C$18/D8 -> 1.1223889 | S8: =F8*M8*O8*Q8+J8*L8*P8*R8+0.5*I8*D8*N8*P8*R8 -> 665.41441 | T8: =S8/Entradas!$C$27 -> 221.8048 | U8: =AI8 -> 228.02054 | V8: =MIN(T8,U8) -> 221.8048 | W8: =Entradas!E8 -> 1915.2 | X8: =Entradas!$C$20*W8/(Entradas!$C$21*D8*(1-Entradas!E9^2))+J8 -> 51.137042 | Y8: =MIN(V8,X8) -> 51.137042 | Z8: =IF(X8<V8,"Asentamiento",IF(T8<=U8,"Falla (FSICP)","Falla (FSB directo)")) -> Asentamiento | AA8: =MIN(S8/Entradas!$C$28,AO8) -> 266.16577 | AB8: =MIN(S8/Entradas!$C$29,AU8) -> 443.60961 | AD8: =DEGREES(ATAN(TAN(RADIANS(G8))/Entradas!$D$27)) -> 18.761783 | AE8: =TAN(RADIANS(45+AD8/2))^2 -> 1.9482619 | AF8: =EXP(PI()*TAN(RADIANS(AD8)))*AE8 -> 5.6637444 | AG8: =(AF8-1)/TAN(RADIANS(AD8)) -> 13.729671 | AH8: =(AF8-1)*TAN(RADIANS(1.4*AD8)) -> 2.3015738 | AI8: =F8/Entradas!$D$27*AG8*(1+0.2*AE8*Entradas!$C$22)*(1+0.2*SQRT(AE8)*Entradas!$C$18/D8)+J8*AF8*(1+0.1*AE8*Entradas!$C$22)*(1+0.1*SQRT(AE8)*Entradas!$C$18/D8)+0.5*I8*D8*AH8*(1+0.1*AE8*Entradas!$C$22)*(1+0.1*SQRT(AE8)*Entradas!$C$18/D8) -> 228.02054 | AJ8: =DEGREES(ATAN(TAN(RADIANS(G8))/Entradas!$D$28)) -> 22.176809 | AK8: =TAN(RADIANS(45+AJ8/2))^2 -> 2.212676 | AL8: =EXP(PI()*TAN(RADIANS(AJ8)))*AK8 -> 7.9627925 | AM8: =(AL8-1)/TAN(RADIANS(AJ8)) -> 17.081562 | AN8: =(AL8-1)*TAN(RADIANS(1.4*AJ8)) -> 4.1915336 | AO8: =F8/Entradas!$D$28*AM8*(1+0.2*AK8*Entradas!$C$22)*(1+0.2*SQRT(AK8)*Entradas!$C$18/D8)+J8*AL8*(1+0.1*AK8*Entradas!$C$22)*(1+0.1*SQRT(AK8)*Entradas!$C$18/D8)+0.5*I8*D8*AN8*(1+0.1*AK8*Entradas!$C$22)*(1+0.1*SQRT(AK8)*Entradas!$C$18/D8) -> 350.47199 | AP8: =DEGREES(ATAN(TAN(RADIANS(G8))/Entradas!$D$29)) -> 24.853806 | AQ8: =TAN(RADIANS(45+AP8/2))^2 -> 2.4500865 | AR8: =EXP(PI()*TAN(RADIANS(AP8)))*AQ8 -> 10.499468 | AS8: =(AR8-1)/TAN(RADIANS(AP8)) -> 20.508131 | AT8: =(AR8-1)*TAN(RADIANS(1.4*AP8)) -> 6.6011536 | AU8: =F8/Entradas!$D$29*AS8*(1+0.2*AQ8*Entradas!$C$22)*(1+0.2*SQRT(AQ8)*Entradas!$C$18/D8)+J8*AR8*(1+0.1*AQ8*Entradas!$C$22)*(1+0.1*SQRT(AQ8)*Entradas!$C$18/D8)+0.5*I8*D8*AT8*(1+0.1*AQ8*Entradas!$C$22)*(1+0.1*SQRT(AQ8)*Entradas!$C$18/D8) -> 497.48932
A9: S1 | B9: Oriental (Ibagué) | C9: Mínimo | D9: 3 | E9: NF en la base | F9: =Entradas!E5 -> 0 | G9: =Entradas!E6 -> 27 | H9: =Entradas!E7 -> 16 | I9: =IF(E9="NF en la base",H9-Entradas!$C$19,H9) -> 6.19 | J9: =H9*Entradas!$C$18 -> 24 | K9: =TAN(RADIANS(45+G9/2))^2 -> 2.6629399 | L9: =EXP(PI()*TAN(RADIANS(G9)))*K9 -> 13.199146 | M9: =(L9-1)/TAN(RADIANS(G9)) -> 23.942173 | N9: =(L9-1)*TAN(RADIANS(1.4*G9)) -> 9.4626279 | O9: =1+0.2*K9*Entradas!$C$22 -> 1.532588 | P9: =1+0.1*K9*Entradas!$C$22 -> 1.266294 | Q9: =1+0.2*SQRT(K9)*Entradas!$C$18/D9 -> 1.1631852 | R9: =1+0.1*SQRT(K9)*Entradas!$C$18/D9 -> 1.0815926 | S9: =F9*M9*O9*Q9+J9*L9*P9*R9+0.5*I9*D9*N9*P9*R9 -> 554.2007 | T9: =S9/Entradas!$C$27 -> 184.73357 | U9: =AI9 -> 201.06291 | V9: =MIN(T9,U9) -> 184.73357 | W9: =Entradas!E8 -> 1915.2 | X9: =Entradas!$C$20*W9/(Entradas!$C$21*D9*(1-Entradas!E9^2))+J9 -> 42.091361 | Y9: =MIN(V9,X9) -> 42.091361 | Z9: =IF(X9<V9,"Asentamiento",IF(T9<=U9,"Falla (FSICP)","Falla (FSB directo)")) -> Asentamiento | AA9: =MIN(S9/Entradas!$C$28,AO9) -> 221.68028 | AB9: =MIN(S9/Entradas!$C$29,AU9) -> 369.46714 | AD9: =DEGREES(ATAN(TAN(RADIANS(G9))/Entradas!$D$27)) -> 18.761783 | AE9: =TAN(RADIANS(45+AD9/2))^2 -> 1.9482619 | AF9: =EXP(PI()*TAN(RADIANS(AD9)))*AE9 -> 5.6637444 | AG9: =(AF9-1)/TAN(RADIANS(AD9)) -> 13.729671 | AH9: =(AF9-1)*TAN(RADIANS(1.4*AD9)) -> 2.3015738 | AI9: =F9/Entradas!$D$27*AG9*(1+0.2*AE9*Entradas!$C$22)*(1+0.2*SQRT(AE9)*Entradas!$C$18/D9)+J9*AF9*(1+0.1*AE9*Entradas!$C$22)*(1+0.1*SQRT(AE9)*Entradas!$C$18/D9)+0.5*I9*D9*AH9*(1+0.1*AE9*Entradas!$C$22)*(1+0.1*SQRT(AE9)*Entradas!$C$18/D9) -> 201.06291 | AJ9: =DEGREES(ATAN(TAN(RADIANS(G9))/Entradas!$D$28)) -> 22.176809 | AK9: =TAN(RADIANS(45+AJ9/2))^2 -> 2.212676 | AL9: =EXP(PI()*TAN(RADIANS(AJ9)))*AK9 -> 7.9627925 | AM9: =(AL9-1)/TAN(RADIANS(AJ9)) -> 17.081562 | AN9: =(AL9-1)*TAN(RADIANS(1.4*AJ9)) -> 4.1915336 | AO9: =F9/Entradas!$D$28*AM9*(1+0.2*AK9*Entradas!$C$22)*(1+0.2*SQRT(AK9)*Entradas!$C$18/D9)+J9*AL9*(1+0.1*AK9*Entradas!$C$22)*(1+0.1*SQRT(AK9)*Entradas!$C$18/D9)+0.5*I9*D9*AN9*(1+0.1*AK9*Entradas!$C$22)*(1+0.1*SQRT(AK9)*Entradas!$C$18/D9) -> 301.81629 | AP9: =DEGREES(ATAN(TAN(RADIANS(G9))/Entradas!$D$29)) -> 24.853806 | AQ9: =TAN(RADIANS(45+AP9/2))^2 -> 2.4500865 | AR9: =EXP(PI()*TAN(RADIANS(AP9)))*AQ9 -> 10.499468 | AS9: =(AR9-1)/TAN(RADIANS(AP9)) -> 20.508131 | AT9: =(AR9-1)*TAN(RADIANS(1.4*AP9)) -> 6.6011536 | AU9: =F9/Entradas!$D$29*AS9*(1+0.2*AQ9*Entradas!$C$22)*(1+0.2*SQRT(AQ9)*Entradas!$C$18/D9)+J9*AR9*(1+0.1*AQ9*Entradas!$C$22)*(1+0.1*SQRT(AQ9)*Entradas!$C$18/D9)+0.5*I9*D9*AT9*(1+0.1*AQ9*Entradas!$C$22)*(1+0.1*SQRT(AQ9)*Entradas!$C$18/D9) -> 420.5606
A10: S1 | B10: Oriental (Ibagué) | C10: Mínimo | D10: 3 | E10: NF profundo | F10: =Entradas!E5 -> 0 | G10: =Entradas!E6 -> 27 | H10: =Entradas!E7 -> 16 | I10: =IF(E10="NF en la base",H10-Entradas!$C$19,H10) -> 16 | J10: =H10*Entradas!$C$18 -> 24 | K10: =TAN(RADIANS(45+G10/2))^2 -> 2.6629399 | L10: =EXP(PI()*TAN(RADIANS(G10)))*K10 -> 13.199146 | M10: =(L10-1)/TAN(RADIANS(G10)) -> 23.942173 | N10: =(L10-1)*TAN(RADIANS(1.4*G10)) -> 9.4626279 | O10: =1+0.2*K10*Entradas!$C$22 -> 1.532588 | P10: =1+0.1*K10*Entradas!$C$22 -> 1.266294 | Q10: =1+0.2*SQRT(K10)*Entradas!$C$18/D10 -> 1.1631852 | R10: =1+0.1*SQRT(K10)*Entradas!$C$18/D10 -> 1.0815926 | S10: =F10*M10*O10*Q10+J10*L10*P10*R10+0.5*I10*D10*N10*P10*R10 -> 744.9093 | T10: =S10/Entradas!$C$27 -> 248.3031 | U10: =AI10 -> 244.353 | V10: =MIN(T10,U10) -> 244.353 | W10: =Entradas!E8 -> 1915.2 | X10: =Entradas!$C$20*W10/(Entradas!$C$21*D10*(1-Entradas!E9^2))+J10 -> 42.091361 | Y10: =MIN(V10,X10) -> 42.091361 | Z10: =IF(X10<V10,"Asentamiento",IF(T10<=U10,"Falla (FSICP)","Falla (FSB directo)")) -> Asentamiento | AA10: =MIN(S10/Entradas!$C$28,AO10) -> 297.96372 | AB10: =MIN(S10/Entradas!$C$29,AU10) -> 496.6062 | AD10: =DEGREES(ATAN(TAN(RADIANS(G10))/Entradas!$D$27)) -> 18.761783 | AE10: =TAN(RADIANS(45+AD10/2))^2 -> 1.9482619 | AF10: =EXP(PI()*TAN(RADIANS(AD10)))*AE10 -> 5.6637444 | AG10: =(AF10-1)/TAN(RADIANS(AD10)) -> 13.729671 | AH10: =(AF10-1)*TAN(RADIANS(1.4*AD10)) -> 2.3015738 | AI10: =F10/Entradas!$D$27*AG10*(1+0.2*AE10*Entradas!$C$22)*(1+0.2*SQRT(AE10)*Entradas!$C$18/D10)+J10*AF10*(1+0.1*AE10*Entradas!$C$22)*(1+0.1*SQRT(AE10)*Entradas!$C$18/D10)+0.5*I10*D10*AH10*(1+0.1*AE10*Entradas!$C$22)*(1+0.1*SQRT(AE10)*Entradas!$C$18/D10) -> 244.353 | AJ10: =DEGREES(ATAN(TAN(RADIANS(G10))/Entradas!$D$28)) -> 22.176809 | AK10: =TAN(RADIANS(45+AJ10/2))^2 -> 2.212676 | AL10: =EXP(PI()*TAN(RADIANS(AJ10)))*AK10 -> 7.9627925 | AM10: =(AL10-1)/TAN(RADIANS(AJ10)) -> 17.081562 | AN10: =(AL10-1)*TAN(RADIANS(1.4*AJ10)) -> 4.1915336 | AO10: =F10/Entradas!$D$28*AM10*(1+0.2*AK10*Entradas!$C$22)*(1+0.2*SQRT(AK10)*Entradas!$C$18/D10)+J10*AL10*(1+0.1*AK10*Entradas!$C$22)*(1+0.1*SQRT(AK10)*Entradas!$C$18/D10)+0.5*I10*D10*AN10*(1+0.1*AK10*Entradas!$C$22)*(1+0.1*SQRT(AK10)*Entradas!$C$18/D10) -> 382.74453 | AP10: =DEGREES(ATAN(TAN(RADIANS(G10))/Entradas!$D$29)) -> 24.853806 | AQ10: =TAN(RADIANS(45+AP10/2))^2 -> 2.4500865 | AR10: =EXP(PI()*TAN(RADIANS(AP10)))*AQ10 -> 10.499468 | AS10: =(AR10-1)/TAN(RADIANS(AP10)) -> 20.508131 | AT10: =(AR10-1)*TAN(RADIANS(1.4*AP10)) -> 6.6011536 | AU10: =F10/Entradas!$D$29*AS10*(1+0.2*AQ10*Entradas!$C$22)*(1+0.2*SQRT(AQ10)*Entradas!$C$18/D10)+J10*AR10*(1+0.1*AQ10*Entradas!$C$22)*(1+0.1*SQRT(AQ10)*Entradas!$C$18/D10)+0.5*I10*D10*AT10*(1+0.1*AQ10*Entradas!$C$22)*(1+0.1*SQRT(AQ10)*Entradas!$C$18/D10) -> 550.96057
A11: S1 | B11: Oriental (Ibagué) | C11: Típico | D11: 1.5 | E11: NF en la base | F11: =Entradas!F5 -> 15 | G11: =Entradas!F6 -> 30 | H11: =Entradas!F7 -> 17 | I11: =IF(E11="NF en la base",H11-Entradas!$C$19,H11) -> 7.19 | J11: =H11*Entradas!$C$18 -> 25.5 | K11: =TAN(RADIANS(45+G11/2))^2 -> 3 | L11: =EXP(PI()*TAN(RADIANS(G11)))*K11 -> 18.401122 | M11: =(L11-1)/TAN(RADIANS(G11)) -> 30.139628 | N11: =(L11-1)*TAN(RADIANS(1.4*G11)) -> 15.668041 | O11: =1+0.2*K11*Entradas!$C$22 -> 1.6 | P11: =1+0.1*K11*Entradas!$C$22 -> 1.3 | Q11: =1+0.2*SQRT(K11)*Entradas!$C$18/D11 -> 1.3464102 | R11: =1+0.1*SQRT(K11)*Entradas!$C$18/D11 -> 1.1732051 | S11: =F11*M11*O11*Q11+J11*L11*P11*R11+0.5*I11*D11*N11*P11*R11 -> 1818.4402 | T11: =S11/Entradas!$C$27 -> 606.14674 | U11: =AI11 -> 569.35303 | V11: =MIN(T11,U11) -> 569.35303 | W11: =Entradas!F8 -> 10533.6 | X11: =Entradas!$C$20*W11/(Entradas!$C$21*D11*(1-Entradas!F9^2))+J11 -> 224.50498 | Y11: =MIN(V11,X11) -> 224.50498 | Z11: =IF(X11<V11,"Asentamiento",IF(T11<=U11,"Falla (FSICP)","Falla (FSB directo)")) -> Asentamiento | AA11: =MIN(S11/Entradas!$C$28,AO11) -> 727.37609 | AB11: =MIN(S11/Entradas!$C$29,AU11) -> 1212.2935 | AD11: =DEGREES(ATAN(TAN(RADIANS(G11))/Entradas!$D$27)) -> 21.051724 | AE11: =TAN(RADIANS(45+AD11/2))^2 -> 2.1211503 | AF11: =EXP(PI()*TAN(RADIANS(AD11)))*AE11 -> 7.1075536 | AG11: =(AF11-1)/TAN(RADIANS(AD11)) -> 15.86789 | AH11: =(AF11-1)*TAN(RADIANS(1.4*AD11)) -> 3.4516068 | AI11: =F11/Entradas!$D$27*AG11*(1+0.2*AE11*Entradas!$C$22)*(1+0.2*SQRT(AE11)*Entradas!$C$18/D11)+J11*AF11*(1+0.1*AE11*Entradas!$C$22)*(1+0.1*SQRT(AE11)*Entradas!$C$18/D11)+0.5*I11*D11*AH11*(1+0.1*AE11*Entradas!$C$22)*(1+0.1*SQRT(AE11)*Entradas!$C$18/D11) -> 569.35303 | AJ11: =DEGREES(ATAN(TAN(RADIANS(G11))/Entradas!$D$28)) -> 24.791281 | AK11: =TAN(RADIANS(45+AJ11/2))^2 -> 2.4442018 | AL11: =EXP(PI()*TAN(RADIANS(AJ11)))*AK11 -> 10.430749 | AM11: =(AL11-1)/TAN(RADIANS(AJ11)) -> 20.418171 | AN11: =(AL11-1)*TAN(RADIANS(1.4*AJ11)) -> 6.5320584 | AO11: =F11/Entradas!$D$28*AM11*(1+0.2*AK11*Entradas!$C$22)*(1+0.2*SQRT(AK11)*Entradas!$C$18/D11)+J11*AL11*(1+0.1*AK11*Entradas!$C$22)*(1+0.1*SQRT(AK11)*Entradas!$C$18/D11)+0.5*I11*D11*AN11*(1+0.1*AK11*Entradas!$C$22)*(1+0.1*SQRT(AK11)*Entradas!$C$18/D11) -> 912.28601 | AP11: =DEGREES(ATAN(TAN(RADIANS(G11))/Entradas!$D$29)) -> 27.693359 | AQ11: =TAN(RADIANS(45+AP11/2))^2 -> 2.7364978 | AR11: =EXP(PI()*TAN(RADIANS(AP11)))*AQ11 -> 14.233345 | AS11: =(AR11-1)/TAN(RADIANS(AP11)) -> 25.212908 | AT11: =(AR11-1)*TAN(RADIANS(1.4*AP11)) -> 10.628746 | AU11: =F11/Entradas!$D$29*AS11*(1+0.2*AQ11*Entradas!$C$22)*(1+0.2*SQRT(AQ11)*Entradas!$C$18/D11)+J11*AR11*(1+0.1*AQ11*Entradas!$C$22)*(1+0.1*SQRT(AQ11)*Entradas!$C$18/D11)+0.5*I11*D11*AT11*(1+0.1*AQ11*Entradas!$C$22)*(1+0.1*SQRT(AQ11)*Entradas!$C$18/D11) -> 1331.8031
A12: S1 | B12: Oriental (Ibagué) | C12: Típico | D12: 1.5 | E12: NF profundo | F12: =Entradas!F5 -> 15 | G12: =Entradas!F6 -> 30 | H12: =Entradas!F7 -> 17 | I12: =IF(E12="NF en la base",H12-Entradas!$C$19,H12) -> 17 | J12: =H12*Entradas!$C$18 -> 25.5 | K12: =TAN(RADIANS(45+G12/2))^2 -> 3 | L12: =EXP(PI()*TAN(RADIANS(G12)))*K12 -> 18.401122 | M12: =(L12-1)/TAN(RADIANS(G12)) -> 30.139628 | N12: =(L12-1)*TAN(RADIANS(1.4*G12)) -> 15.668041 | O12: =1+0.2*K12*Entradas!$C$22 -> 1.6 | P12: =1+0.1*K12*Entradas!$C$22 -> 1.3 | Q12: =1+0.2*SQRT(K12)*Entradas!$C$18/D12 -> 1.3464102 | R12: =1+0.1*SQRT(K12)*Entradas!$C$18/D12 -> 1.1732051 | S12: =F12*M12*O12*Q12+J12*L12*P12*R12+0.5*I12*D12*N12*P12*R12 -> 1994.2578 | T12: =S12/Entradas!$C$27 -> 664.7526 | U12: =AI12 -> 604.61805 | V12: =MIN(T12,U12) -> 604.61805 | W12: =Entradas!F8 -> 10533.6 | X12: =Entradas!$C$20*W12/(Entradas!$C$21*D12*(1-Entradas!F9^2))+J12 -> 224.50498 | Y12: =MIN(V12,X12) -> 224.50498 | Z12: =IF(X12<V12,"Asentamiento",IF(T12<=U12,"Falla (FSICP)","Falla (FSB directo)")) -> Asentamiento | AA12: =MIN(S12/Entradas!$C$28,AO12) -> 797.70312 | AB12: =MIN(S12/Entradas!$C$29,AU12) -> 1329.5052 | AD12: =DEGREES(ATAN(TAN(RADIANS(G12))/Entradas!$D$27)) -> 21.051724 | AE12: =TAN(RADIANS(45+AD12/2))^2 -> 2.1211503 | AF12: =EXP(PI()*TAN(RADIANS(AD12)))*AE12 -> 7.1075536 | AG12: =(AF12-1)/TAN(RADIANS(AD12)) -> 15.86789 | AH12: =(AF12-1)*TAN(RADIANS(1.4*AD12)) -> 3.4516068 | AI12: =F12/Entradas!$D$27*AG12*(1+0.2*AE12*Entradas!$C$22)*(1+0.2*SQRT(AE12)*Entradas!$C$18/D12)+J12*AF12*(1+0.1*AE12*Entradas!$C$22)*(1+0.1*SQRT(AE12)*Entradas!$C$18/D12)+0.5*I12*D12*AH12*(1+0.1*AE12*Entradas!$C$22)*(1+0.1*SQRT(AE12)*Entradas!$C$18/D12) -> 604.61805 | AJ12: =DEGREES(ATAN(TAN(RADIANS(G12))/Entradas!$D$28)) -> 24.791281 | AK12: =TAN(RADIANS(45+AJ12/2))^2 -> 2.4442018 | AL12: =EXP(PI()*TAN(RADIANS(AJ12)))*AK12 -> 10.430749 | AM12: =(AL12-1)/TAN(RADIANS(AJ12)) -> 20.418171 | AN12: =(AL12-1)*TAN(RADIANS(1.4*AJ12)) -> 6.5320584 | AO12: =F12/Entradas!$D$28*AM12*(1+0.2*AK12*Entradas!$C$22)*(1+0.2*SQRT(AK12)*Entradas!$C$18/D12)+J12*AL12*(1+0.1*AK12*Entradas!$C$22)*(1+0.1*SQRT(AK12)*Entradas!$C$18/D12)+0.5*I12*D12*AN12*(1+0.1*AK12*Entradas!$C$22)*(1+0.1*SQRT(AK12)*Entradas!$C$18/D12) -> 981.44246 | AP12: =DEGREES(ATAN(TAN(RADIANS(G12))/Entradas!$D$29)) -> 27.693359 | AQ12: =TAN(RADIANS(45+AP12/2))^2 -> 2.7364978 | AR12: =EXP(PI()*TAN(RADIANS(AP12)))*AQ12 -> 14.233345 | AS12: =(AR12-1)/TAN(RADIANS(AP12)) -> 25.212908 | AT12: =(AR12-1)*TAN(RADIANS(1.4*AP12)) -> 10.628746 | AU12: =F12/Entradas!$D$29*AS12*(1+0.2*AQ12*Entradas!$C$22)*(1+0.2*SQRT(AQ12)*Entradas!$C$18/D12)+J12*AR12*(1+0.1*AQ12*Entradas!$C$22)*(1+0.1*SQRT(AQ12)*Entradas!$C$18/D12)+0.5*I12*D12*AT12*(1+0.1*AQ12*Entradas!$C$22)*(1+0.1*SQRT(AQ12)*Entradas!$C$18/D12) -> 1447.8801
A13: S1 | B13: Oriental (Ibagué) | C13: Típico | D13: 2 | E13: NF en la base | F13: =Entradas!F5 -> 15 | G13: =Entradas!F6 -> 30 | H13: =Entradas!F7 -> 17 | I13: =IF(E13="NF en la base",H13-Entradas!$C$19,H13) -> 7.19 | J13: =H13*Entradas!$C$18 -> 25.5 | K13: =TAN(RADIANS(45+G13/2))^2 -> 3 | L13: =EXP(PI()*TAN(RADIANS(G13)))*K13 -> 18.401122 | M13: =(L13-1)/TAN(RADIANS(G13)) -> 30.139628 | N13: =(L13-1)*TAN(RADIANS(1.4*G13)) -> 15.668041 | O13: =1+0.2*K13*Entradas!$C$22 -> 1.6 | P13: =1+0.1*K13*Entradas!$C$22 -> 1.3 | Q13: =1+0.2*SQRT(K13)*Entradas!$C$18/D13 -> 1.2598076 | R13: =1+0.1*SQRT(K13)*Entradas!$C$18/D13 -> 1.1299038 | S13: =F13*M13*O13*Q13+J13*L13*P13*R13+0.5*I13*D13*N13*P13*R13 -> 1765.9948 | T13: =S13/Entradas!$C$27 -> 588.66494 | U13: =AI13 -> 552.41725 | V13: =MIN(T13,U13) -> 552.41725 | W13: =Entradas!F8 -> 10533.6 | X13: =Entradas!$C$20*W13/(Entradas!$C$21*D13*(1-Entradas!F9^2))+J13 -> 174.75373 | Y13: =MIN(V13,X13) -> 174.75373 | Z13: =IF(X13<V13,"Asentamiento",IF(T13<=U13,"Falla (FSICP)","Falla (FSB directo)")) -> Asentamiento | AA13: =MIN(S13/Entradas!$C$28,AO13) -> 706.39793 | AB13: =MIN(S13/Entradas!$C$29,AU13) -> 1177.3299 | AD13: =DEGREES(ATAN(TAN(RADIANS(G13))/Entradas!$D$27)) -> 21.051724 | AE13: =TAN(RADIANS(45+AD13/2))^2 -> 2.1211503 | AF13: =EXP(PI()*TAN(RADIANS(AD13)))*AE13 -> 7.1075536 | AG13: =(AF13-1)/TAN(RADIANS(AD13)) -> 15.86789 | AH13: =(AF13-1)*TAN(RADIANS(1.4*AD13)) -> 3.4516068 | AI13: =F13/Entradas!$D$27*AG13*(1+0.2*AE13*Entradas!$C$22)*(1+0.2*SQRT(AE13)*Entradas!$C$18/D13)+J13*AF13*(1+0.1*AE13*Entradas!$C$22)*(1+0.1*SQRT(AE13)*Entradas!$C$18/D13)+0.5*I13*D13*AH13*(1+0.1*AE13*Entradas!$C$22)*(1+0.1*SQRT(AE13)*Entradas!$C$18/D13) -> 552.41725 | AJ13: =DEGREES(ATAN(TAN(RADIANS(G13))/Entradas!$D$28)) -> 24.791281 | AK13: =TAN(RADIANS(45+AJ13/2))^2 -> 2.4442018 | AL13: =EXP(PI()*TAN(RADIANS(AJ13)))*AK13 -> 10.430749 | AM13: =(AL13-1)/TAN(RADIANS(AJ13)) -> 20.418171 | AN13: =(AL13-1)*TAN(RADIANS(1.4*AJ13)) -> 6.5320584 | AO13: =F13/Entradas!$D$28*AM13*(1+0.2*AK13*Entradas!$C$22)*(1+0.2*SQRT(AK13)*Entradas!$C$18/D13)+J13*AL13*(1+0.1*AK13*Entradas!$C$22)*(1+0.1*SQRT(AK13)*Entradas!$C$18/D13)+0.5*I13*D13*AN13*(1+0.1*AK13*Entradas!$C$22)*(1+0.1*SQRT(AK13)*Entradas!$C$18/D13) -> 885.44453 | AP13: =DEGREES(ATAN(TAN(RADIANS(G13))/Entradas!$D$29)) -> 27.693359 | AQ13: =TAN(RADIANS(45+AP13/2))^2 -> 2.7364978 | AR13: =EXP(PI()*TAN(RADIANS(AP13)))*AQ13 -> 14.233345 | AS13: =(AR13-1)/TAN(RADIANS(AP13)) -> 25.212908 | AT13: =(AR13-1)*TAN(RADIANS(1.4*AP13)) -> 10.628746 | AU13: =F13/Entradas!$D$29*AS13*(1+0.2*AQ13*Entradas!$C$22)*(1+0.2*SQRT(AQ13)*Entradas!$C$18/D13)+J13*AR13*(1+0.1*AQ13*Entradas!$C$22)*(1+0.1*SQRT(AQ13)*Entradas!$C$18/D13)+0.5*I13*D13*AT13*(1+0.1*AQ13*Entradas!$C$22)*(1+0.1*SQRT(AQ13)*Entradas!$C$18/D13) -> 1293.0177
A14: S1 | B14: Oriental (Ibagué) | C14: Típico | D14: 2 | E14: NF profundo | F14: =Entradas!F5 -> 15 | G14: =Entradas!F6 -> 30 | H14: =Entradas!F7 -> 17 | I14: =IF(E14="NF en la base",H14-Entradas!$C$19,H14) -> 17 | J14: =H14*Entradas!$C$18 -> 25.5 | K14: =TAN(RADIANS(45+G14/2))^2 -> 3 | L14: =EXP(PI()*TAN(RADIANS(G14)))*K14 -> 18.401122 | M14: =(L14-1)/TAN(RADIANS(G14)) -> 30.139628 | N14: =(L14-1)*TAN(RADIANS(1.4*G14)) -> 15.668041 | O14: =1+0.2*K14*Entradas!$C$22 -> 1.6 | P14: =1+0.1*K14*Entradas!$C$22 -> 1.3 | Q14: =1+0.2*SQRT(K14)*Entradas!$C$18/D14 -> 1.2598076 | R14: =1+0.1*SQRT(K14)*Entradas!$C$18/D14 -> 1.1299038 | S14: =F14*M14*O14*Q14+J14*L14*P14*R14+0.5*I14*D14*N14*P14*R14 -> 1991.766 | T14: =S14/Entradas!$C$27 -> 663.92201 | U14: =AI14 -> 597.94291 | V14: =MIN(T14,U14) -> 597.94291 | W14: =Entradas!F8 -> 10533.6 | X14: =Entradas!$C$20*W14/(Entradas!$C$21*D14*(1-Entradas!F9^2))+J14 -> 174.75373 | Y14: =MIN(V14,X14) -> 174.75373 | Z14: =IF(X14<V14,"Asentamiento",IF(T14<=U14,"Falla (FSICP)","Falla (FSB directo)")) -> Asentamiento | AA14: =MIN(S14/Entradas!$C$28,AO14) -> 796.70641 | AB14: =MIN(S14/Entradas!$C$29,AU14) -> 1327.844 | AD14: =DEGREES(ATAN(TAN(RADIANS(G14))/Entradas!$D$27)) -> 21.051724 | AE14: =TAN(RADIANS(45+AD14/2))^2 -> 2.1211503 | AF14: =EXP(PI()*TAN(RADIANS(AD14)))*AE14 -> 7.1075536 | AG14: =(AF14-1)/TAN(RADIANS(AD14)) -> 15.86789 | AH14: =(AF14-1)*TAN(RADIANS(1.4*AD14)) -> 3.4516068 | AI14: =F14/Entradas!$D$27*AG14*(1+0.2*AE14*Entradas!$C$22)*(1+0.2*SQRT(AE14)*Entradas!$C$18/D14)+J14*AF14*(1+0.1*AE14*Entradas!$C$22)*(1+0.1*SQRT(AE14)*Entradas!$C$18/D14)+0.5*I14*D14*AH14*(1+0.1*AE14*Entradas!$C$22)*(1+0.1*SQRT(AE14)*Entradas!$C$18/D14) -> 597.94291 | AJ14: =DEGREES(ATAN(TAN(RADIANS(G14))/Entradas!$D$28)) -> 24.791281 | AK14: =TAN(RADIANS(45+AJ14/2))^2 -> 2.4442018 | AL14: =EXP(PI()*TAN(RADIANS(AJ14)))*AK14 -> 10.430749 | AM14: =(AL14-1)/TAN(RADIANS(AJ14)) -> 20.418171 | AN14: =(AL14-1)*TAN(RADIANS(1.4*AJ14)) -> 6.5320584 | AO14: =F14/Entradas!$D$28*AM14*(1+0.2*AK14*Entradas!$C$22)*(1+0.2*SQRT(AK14)*Entradas!$C$18/D14)+J14*AL14*(1+0.1*AK14*Entradas!$C$22)*(1+0.1*SQRT(AK14)*Entradas!$C$18/D14)+0.5*I14*D14*AN14*(1+0.1*AK14*Entradas!$C$22)*(1+0.1*SQRT(AK14)*Entradas!$C$18/D14) -> 974.53644 | AP14: =DEGREES(ATAN(TAN(RADIANS(G14))/Entradas!$D$29)) -> 27.693359 | AQ14: =TAN(RADIANS(45+AP14/2))^2 -> 2.7364978 | AR14: =EXP(PI()*TAN(RADIANS(AP14)))*AQ14 -> 14.233345 | AS14: =(AR14-1)/TAN(RADIANS(AP14)) -> 25.212908 | AT14: =(AR14-1)*TAN(RADIANS(1.4*AP14)) -> 10.628746 | AU14: =F14/Entradas!$D$29*AS14*(1+0.2*AQ14*Entradas!$C$22)*(1+0.2*SQRT(AQ14)*Entradas!$C$18/D14)+J14*AR14*(1+0.1*AQ14*Entradas!$C$22)*(1+0.1*SQRT(AQ14)*Entradas!$C$18/D14)+0.5*I14*D14*AT14*(1+0.1*AQ14*Entradas!$C$22)*(1+0.1*SQRT(AQ14)*Entradas!$C$18/D14) -> 1442.2949
A15: S1 | B15: Oriental (Ibagué) | C15: Típico | D15: 3 | E15: NF en la base | F15: =Entradas!F5 -> 15 | G15: =Entradas!F6 -> 30 | H15: =Entradas!F7 -> 17 | I15: =IF(E15="NF en la base",H15-Entradas!$C$19,H15) -> 7.19 | J15: =H15*Entradas!$C$18 -> 25.5 | K15: =TAN(RADIANS(45+G15/2))^2 -> 3 | L15: =EXP(PI()*TAN(RADIANS(G15)))*K15 -> 18.401122 | M15: =(L15-1)/TAN(RADIANS(G15)) -> 30.139628 | N15: =(L15-1)*TAN(RADIANS(1.4*G15)) -> 15.668041 | O15: =1+0.2*K15*Entradas!$C$22 -> 1.6 | P15: =1+0.1*K15*Entradas!$C$22 -> 1.3 | Q15: =1+0.2*SQRT(K15)*Entradas!$C$18/D15 -> 1.1732051 | R15: =1+0.1*SQRT(K15)*Entradas!$C$18/D15 -> 1.0866025 | S15: =F15*M15*O15*Q15+J15*L15*P15*R15+0.5*I15*D15*N15*P15*R15 -> 1750.1617 | T15: =S15/Entradas!$C$27 -> 583.38724 | U15: =AI15 -> 543.00175 | V15: =MIN(T15,U15) -> 543.00175 | W15: =Entradas!F8 -> 10533.6 | X15: =Entradas!$C$20*W15/(Entradas!$C$21*D15*(1-Entradas!F9^2))+J15 -> 125.00249 | Y15: =MIN(V15,X15) -> 125.00249 | Z15: =IF(X15<V15,"Asentamiento",IF(T15<=U15,"Falla (FSICP)","Falla (FSB directo)")) -> Asentamiento | AA15: =MIN(S15/Entradas!$C$28,AO15) -> 700.06469 | AB15: =MIN(S15/Entradas!$C$29,AU15) -> 1166.7745 | AD15: =DEGREES(ATAN(TAN(RADIANS(G15))/Entradas!$D$27)) -> 21.051724 | AE15: =TAN(RADIANS(45+AD15/2))^2 -> 2.1211503 | AF15: =EXP(PI()*TAN(RADIANS(AD15)))*AE15 -> 7.1075536 | AG15: =(AF15-1)/TAN(RADIANS(AD15)) -> 15.86789 | AH15: =(AF15-1)*TAN(RADIANS(1.4*AD15)) -> 3.4516068 | AI15: =F15/Entradas!$D$27*AG15*(1+0.2*AE15*Entradas!$C$22)*(1+0.2*SQRT(AE15)*Entradas!$C$18/D15)+J15*AF15*(1+0.1*AE15*Entradas!$C$22)*(1+0.1*SQRT(AE15)*Entradas!$C$18/D15)+0.5*I15*D15*AH15*(1+0.1*AE15*Entradas!$C$22)*(1+0.1*SQRT(AE15)*Entradas!$C$18/D15) -> 543.00175 | AJ15: =DEGREES(ATAN(TAN(RADIANS(G15))/Entradas!$D$28)) -> 24.791281 | AK15: =TAN(RADIANS(45+AJ15/2))^2 -> 2.4442018 | AL15: =EXP(PI()*TAN(RADIANS(AJ15)))*AK15 -> 10.430749 | AM15: =(AL15-1)/TAN(RADIANS(AJ15)) -> 20.418171 | AN15: =(AL15-1)*TAN(RADIANS(1.4*AJ15)) -> 6.5320584 | AO15: =F15/Entradas!$D$28*AM15*(1+0.2*AK15*Entradas!$C$22)*(1+0.2*SQRT(AK15)*Entradas!$C$18/D15)+J15*AL15*(1+0.1*AK15*Entradas!$C$22)*(1+0.1*SQRT(AK15)*Entradas!$C$18/D15)+0.5*I15*D15*AN15*(1+0.1*AK15*Entradas!$C$22)*(1+0.1*SQRT(AK15)*Entradas!$C$18/D15) -> 873.21426 | AP15: =DEGREES(ATAN(TAN(RADIANS(G15))/Entradas!$D$29)) -> 27.693359 | AQ15: =TAN(RADIANS(45+AP15/2))^2 -> 2.7364978 | AR15: =EXP(PI()*TAN(RADIANS(AP15)))*AQ15 -> 14.233345 | AS15: =(AR15-1)/TAN(RADIANS(AP15)) -> 25.212908 | AT15: =(AR15-1)*TAN(RADIANS(1.4*AP15)) -> 10.628746 | AU15: =F15/Entradas!$D$29*AS15*(1+0.2*AQ15*Entradas!$C$22)*(1+0.2*SQRT(AQ15)*Entradas!$C$18/D15)+J15*AR15*(1+0.1*AQ15*Entradas!$C$22)*(1+0.1*SQRT(AQ15)*Entradas!$C$18/D15)+0.5*I15*D15*AT15*(1+0.1*AQ15*Entradas!$C$22)*(1+0.1*SQRT(AQ15)*Entradas!$C$18/D15) -> 1278.5655
A16: S1 | B16: Oriental (Ibagué) | C16: Típico | D16: 3 | E16: NF profundo | F16: =Entradas!F5 -> 15 | G16: =Entradas!F6 -> 30 | H16: =Entradas!F7 -> 17 | I16: =IF(E16="NF en la base",H16-Entradas!$C$19,H16) -> 17 | J16: =H16*Entradas!$C$18 -> 25.5 | K16: =TAN(RADIANS(45+G16/2))^2 -> 3 | L16: =EXP(PI()*TAN(RADIANS(G16)))*K16 -> 18.401122 | M16: =(L16-1)/TAN(RADIANS(G16)) -> 30.139628 | N16: =(L16-1)*TAN(RADIANS(1.4*G16)) -> 15.668041 | O16: =1+0.2*K16*Entradas!$C$22 -> 1.6 | P16: =1+0.1*K16*Entradas!$C$22 -> 1.3 | Q16: =1+0.2*SQRT(K16)*Entradas!$C$18/D16 -> 1.1732051 | R16: =1+0.1*SQRT(K16)*Entradas!$C$18/D16 -> 1.0866025 | S16: =F16*M16*O16*Q16+J16*L16*P16*R16+0.5*I16*D16*N16*P16*R16 -> 2075.8402 | T16: =S16/Entradas!$C$27 -> 691.94673 | U16: =AI16 -> 609.04868 | V16: =MIN(T16,U16) -> 609.04868 | W16: =Entradas!F8 -> 10533.6 | X16: =Entradas!$C$20*W16/(Entradas!$C$21*D16*(1-Entradas!F9^2))+J16 -> 125.00249 | Y16: =MIN(V16,X16) -> 125.00249 | Z16: =IF(X16<V16,"Asentamiento",IF(T16<=U16,"Falla (FSICP)","Falla (FSB directo)")) -> Asentamiento | AA16: =MIN(S16/Entradas!$C$28,AO16) -> 830.33607 | AB16: =MIN(S16/Entradas!$C$29,AU16) -> 1383.8935 | AD16: =DEGREES(ATAN(TAN(RADIANS(G16))/Entradas!$D$27)) -> 21.051724 | AE16: =TAN(RADIANS(45+AD16/2))^2 -> 2.1211503 | AF16: =EXP(PI()*TAN(RADIANS(AD16)))*AE16 -> 7.1075536 | AG16: =(AF16-1)/TAN(RADIANS(AD16)) -> 15.86789 | AH16: =(AF16-1)*TAN(RADIANS(1.4*AD16)) -> 3.4516068 | AI16: =F16/Entradas!$D$27*AG16*(1+0.2*AE16*Entradas!$C$22)*(1+0.2*SQRT(AE16)*Entradas!$C$18/D16)+J16*AF16*(1+0.1*AE16*Entradas!$C$22)*(1+0.1*SQRT(AE16)*Entradas!$C$18/D16)+0.5*I16*D16*AH16*(1+0.1*AE16*Entradas!$C$22)*(1+0.1*SQRT(AE16)*Entradas!$C$18/D16) -> 609.04868 | AJ16: =DEGREES(ATAN(TAN(RADIANS(G16))/Entradas!$D$28)) -> 24.791281 | AK16: =TAN(RADIANS(45+AJ16/2))^2 -> 2.4442018 | AL16: =EXP(PI()*TAN(RADIANS(AJ16)))*AK16 -> 10.430749 | AM16: =(AL16-1)/TAN(RADIANS(AJ16)) -> 20.418171 | AN16: =(AL16-1)*TAN(RADIANS(1.4*AJ16)) -> 6.5320584 | AO16: =F16/Entradas!$D$28*AM16*(1+0.2*AK16*Entradas!$C$22)*(1+0.2*SQRT(AK16)*Entradas!$C$18/D16)+J16*AL16*(1+0.1*AK16*Entradas!$C$22)*(1+0.1*SQRT(AK16)*Entradas!$C$18/D16)+0.5*I16*D16*AN16*(1+0.1*AK16*Entradas!$C$22)*(1+0.1*SQRT(AK16)*Entradas!$C$18/D16) -> 1002.1771 | AP16: =DEGREES(ATAN(TAN(RADIANS(G16))/Entradas!$D$29)) -> 27.693359 | AQ16: =TAN(RADIANS(45+AP16/2))^2 -> 2.7364978 | AR16: =EXP(PI()*TAN(RADIANS(AP16)))*AQ16 -> 14.233345 | AS16: =(AR16-1)/TAN(RADIANS(AP16)) -> 25.212908 | AT16: =(AR16-1)*TAN(RADIANS(1.4*AP16)) -> 10.628746 | AU16: =F16/Entradas!$D$29*AS16*(1+0.2*AQ16*Entradas!$C$22)*(1+0.2*SQRT(AQ16)*Entradas!$C$18/D16)+J16*AR16*(1+0.1*AQ16*Entradas!$C$22)*(1+0.1*SQRT(AQ16)*Entradas!$C$18/D16)+0.5*I16*D16*AT16*(1+0.1*AQ16*Entradas!$C$22)*(1+0.1*SQRT(AQ16)*Entradas!$C$18/D16) -> 1494.2432
A17: S1 | B17: Oriental (Ibagué) | C17: Máximo | D17: 1.5 | E17: NF en la base | F17: =Entradas!G5 -> 29 | G17: =Entradas!G6 -> 32 | H17: =Entradas!G7 -> 18 | I17: =IF(E17="NF en la base",H17-Entradas!$C$19,H17) -> 8.19 | J17: =H17*Entradas!$C$18 -> 27 | K17: =TAN(RADIANS(45+G17/2))^2 -> 3.2545883 | L17: =EXP(PI()*TAN(RADIANS(G17)))*K17 -> 23.176776 | M17: =(L17-1)/TAN(RADIANS(G17)) -> 35.490261 | N17: =(L17-1)*TAN(RADIANS(1.4*G17)) -> 22.022491 | O17: =1+0.2*K17*Entradas!$C$22 -> 1.6509177 | P17: =1+0.1*K17*Entradas!$C$22 -> 1.3254588 | Q17: =1+0.2*SQRT(K17)*Entradas!$C$18/D17 -> 1.3608096 | R17: =1+0.1*SQRT(K17)*Entradas!$C$18/D17 -> 1.1804048 | S17: =F17*M17*O17*Q17+J17*L17*P17*R17+0.5*I17*D17*N17*P17*R17 -> 3502.9402 | T17: =S17/Entradas!$C$27 -> 1167.6467 | U17: =AI17 -> 996.74079 | V17: =MIN(T17,U17) -> 996.74079 | W17: =Entradas!G8 -> 19152 | X17: =Entradas!$C$20*W17/(Entradas!$C$21*D17*(1-Entradas!G9^2))+J17 -> 388.82723 | Y17: =MIN(V17,X17) -> 388.82723 | Z17: =IF(X17<V17,"Asentamiento",IF(T17<=U17,"Falla (FSICP)","Falla (FSB directo)")) -> Asentamiento | AA17: =MIN(S17/Entradas!$C$28,AO17) -> 1401.1761 | AB17: =MIN(S17/Entradas!$C$29,AU17) -> 2335.2935 | AD17: =DEGREES(ATAN(TAN(RADIANS(G17))/Entradas!$D$27)) -> 22.615613 | AE17: =TAN(RADIANS(45+AD17/2))^2 -> 2.2496382 | AF17: =EXP(PI()*TAN(RADIANS(AD17)))*AE17 -> 8.3269124 | AG17: =(AF17-1)/TAN(RADIANS(AD17)) -> 17.588266 | AH17: =(AF17-1)*TAN(RADIANS(1.4*AD17)) -> 4.518458 | AI17: =F17/Entradas!$D$27*AG17*(1+0.2*AE17*Entradas!$C$22)*(1+0.2*SQRT(AE17)*Entradas!$C$18/D17)+J17*AF17*(1+0.1*AE17*Entradas!$C$22)*(1+0.1*SQRT(AE17)*Entradas!$C$18/D17)+0.5*I17*D17*AH17*(1+0.1*AE17*Entradas!$C$22)*(1+0.1*SQRT(AE17)*Entradas!$C$18/D17) -> 996.74079 | AJ17: =DEGREES(ATAN(TAN(RADIANS(G17))/Entradas!$D$28)) -> 26.56026 | AK17: =TAN(RADIANS(45+AJ17/2))^2 -> 2.6175445 | AL17: =EXP(PI()*TAN(RADIANS(AJ17)))*AK17 -> 12.587505 | AM17: =(AL17-1)/TAN(RADIANS(AJ17)) -> 23.179855 | AN17: =(AL17-1)*TAN(RADIANS(1.4*AJ17)) -> 8.790412 | AO17: =F17/Entradas!$D$28*AM17*(1+0.2*AK17*Entradas!$C$22)*(1+0.2*SQRT(AK17)*Entradas!$C$18/D17)+J17*AL17*(1+0.1*AK17*Entradas!$C$22)*(1+0.1*SQRT(AK17)*Entradas!$C$18/D17)+0.5*I17*D17*AN17*(1+0.1*AK17*Entradas!$C$22)*(1+0.1*SQRT(AK17)*Entradas!$C$18/D17) -> 1661.7609 | AP17: =DEGREES(ATAN(TAN(RADIANS(G17))/Entradas!$D$29)) -> 29.599306 | AQ17: =TAN(RADIANS(45+AP17/2))^2 -> 2.9520329 | AR17: =EXP(PI()*TAN(RADIANS(AP17)))*AQ17 -> 17.586239 | AS17: =(AR17-1)/TAN(RADIANS(AP17)) -> 29.197885 | AT17: =(AR17-1)*TAN(RADIANS(1.4*AP17)) -> 14.642829 | AU17: =F17/Entradas!$D$29*AS17*(1+0.2*AQ17*Entradas!$C$22)*(1+0.2*SQRT(AQ17)*Entradas!$C$18/D17)+J17*AR17*(1+0.1*AQ17*Entradas!$C$22)*(1+0.1*SQRT(AQ17)*Entradas!$C$18/D17)+0.5*I17*D17*AT17*(1+0.1*AQ17*Entradas!$C$22)*(1+0.1*SQRT(AQ17)*Entradas!$C$18/D17) -> 2502.0949
A18: S1 | B18: Oriental (Ibagué) | C18: Máximo | D18: 1.5 | E18: NF profundo | F18: =Entradas!G5 -> 29 | G18: =Entradas!G6 -> 32 | H18: =Entradas!G7 -> 18 | I18: =IF(E18="NF en la base",H18-Entradas!$C$19,H18) -> 18 | J18: =H18*Entradas!$C$18 -> 27 | K18: =TAN(RADIANS(45+G18/2))^2 -> 3.2545883 | L18: =EXP(PI()*TAN(RADIANS(G18)))*K18 -> 23.176776 | M18: =(L18-1)/TAN(RADIANS(G18)) -> 35.490261 | N18: =(L18-1)*TAN(RADIANS(1.4*G18)) -> 22.022491 | O18: =1+0.2*K18*Entradas!$C$22 -> 1.6509177 | P18: =1+0.1*K18*Entradas!$C$22 -> 1.3254588 | Q18: =1+0.2*SQRT(K18)*Entradas!$C$18/D18 -> 1.3608096 | R18: =1+0.1*SQRT(K18)*Entradas!$C$18/D18 -> 1.1804048 | S18: =F18*M18*O18*Q18+J18*L18*P18*R18+0.5*I18*D18*N18*P18*R18 -> 3756.4495 | T18: =S18/Entradas!$C$27 -> 1252.1498 | U18: =AI18 -> 1043.5722 | V18: =MIN(T18,U18) -> 1043.5722 | W18: =Entradas!G8 -> 19152 | X18: =Entradas!$C$20*W18/(Entradas!$C$21*D18*(1-Entradas!G9^2))+J18 -> 388.82723 | Y18: =MIN(V18,X18) -> 388.82723 | Z18: =IF(X18<V18,"Asentamiento",IF(T18<=U18,"Falla (FSICP)","Falla (FSB directo)")) -> Asentamiento | AA18: =MIN(S18/Entradas!$C$28,AO18) -> 1502.5798 | AB18: =MIN(S18/Entradas!$C$29,AU18) -> 2504.2997 | AD18: =DEGREES(ATAN(TAN(RADIANS(G18))/Entradas!$D$27)) -> 22.615613 | AE18: =TAN(RADIANS(45+AD18/2))^2 -> 2.2496382 | AF18: =EXP(PI()*TAN(RADIANS(AD18)))*AE18 -> 8.3269124 | AG18: =(AF18-1)/TAN(RADIANS(AD18)) -> 17.588266 | AH18: =(AF18-1)*TAN(RADIANS(1.4*AD18)) -> 4.518458 | AI18: =F18/Entradas!$D$27*AG18*(1+0.2*AE18*Entradas!$C$22)*(1+0.2*SQRT(AE18)*Entradas!$C$18/D18)+J18*AF18*(1+0.1*AE18*Entradas!$C$22)*(1+0.1*SQRT(AE18)*Entradas!$C$18/D18)+0.5*I18*D18*AH18*(1+0.1*AE18*Entradas!$C$22)*(1+0.1*SQRT(AE18)*Entradas!$C$18/D18) -> 1043.5722 | AJ18: =DEGREES(ATAN(TAN(RADIANS(G18))/Entradas!$D$28)) -> 26.56026 | AK18: =TAN(RADIANS(45+AJ18/2))^2 -> 2.6175445 | AL18: =EXP(PI()*TAN(RADIANS(AJ18)))*AK18 -> 12.587505 | AM18: =(AL18-1)/TAN(RADIANS(AJ18)) -> 23.179855 | AN18: =(AL18-1)*TAN(RADIANS(1.4*AJ18)) -> 8.790412 | AO18: =F18/Entradas!$D$28*AM18*(1+0.2*AK18*Entradas!$C$22)*(1+0.2*SQRT(AK18)*Entradas!$C$18/D18)+J18*AL18*(1+0.1*AK18*Entradas!$C$22)*(1+0.1*SQRT(AK18)*Entradas!$C$18/D18)+0.5*I18*D18*AN18*(1+0.1*AK18*Entradas!$C$22)*(1+0.1*SQRT(AK18)*Entradas!$C$18/D18) -> 1756.5681 | AP18: =DEGREES(ATAN(TAN(RADIANS(G18))/Entradas!$D$29)) -> 29.599306 | AQ18: =TAN(RADIANS(45+AP18/2))^2 -> 2.9520329 | AR18: =EXP(PI()*TAN(RADIANS(AP18)))*AQ18 -> 17.586239 | AS18: =(AR18-1)/TAN(RADIANS(AP18)) -> 29.197885 | AT18: =(AR18-1)*TAN(RADIANS(1.4*AP18)) -> 14.642829 | AU18: =F18/Entradas!$D$29*AS18*(1+0.2*AQ18*Entradas!$C$22)*(1+0.2*SQRT(AQ18)*Entradas!$C$18/D18)+J18*AR18*(1+0.1*AQ18*Entradas!$C$22)*(1+0.1*SQRT(AQ18)*Entradas!$C$18/D18)+0.5*I18*D18*AT18*(1+0.1*AQ18*Entradas!$C$22)*(1+0.1*SQRT(AQ18)*Entradas!$C$18/D18) -> 2665.6079
A19: S1 | B19: Oriental (Ibagué) | C19: Máximo | D19: 2 | E19: NF en la base | F19: =Entradas!G5 -> 29 | G19: =Entradas!G6 -> 32 | H19: =Entradas!G7 -> 18 | I19: =IF(E19="NF en la base",H19-Entradas!$C$19,H19) -> 8.19 | J19: =H19*Entradas!$C$18 -> 27 | K19: =TAN(RADIANS(45+G19/2))^2 -> 3.2545883 | L19: =EXP(PI()*TAN(RADIANS(G19)))*K19 -> 23.176776 | M19: =(L19-1)/TAN(RADIANS(G19)) -> 35.490261 | N19: =(L19-1)*TAN(RADIANS(1.4*G19)) -> 22.022491 | O19: =1+0.2*K19*Entradas!$C$22 -> 1.6509177 | P19: =1+0.1*K19*Entradas!$C$22 -> 1.3254588 | Q19: =1+0.2*SQRT(K19)*Entradas!$C$18/D19 -> 1.2706072 | R19: =1+0.1*SQRT(K19)*Entradas!$C$18/D19 -> 1.1353036 | S19: =F19*M19*O19*Q19+J19*L19*P19*R19+0.5*I19*D19*N19*P19*R19 -> 3372.0303 | T19: =S19/Entradas!$C$27 -> 1124.0101 | U19: =AI19 -> 960.77225 | V19: =MIN(T19,U19) -> 960.77225 | W19: =Entradas!G8 -> 19152 | X19: =Entradas!$C$20*W19/(Entradas!$C$21*D19*(1-Entradas!G9^2))+J19 -> 298.37042 | Y19: =MIN(V19,X19) -> 298.37042 | Z19: =IF(X19<V19,"Asentamiento",IF(T19<=U19,"Falla (FSICP)","Falla (FSB directo)")) -> Asentamiento | AA19: =MIN(S19/Entradas!$C$28,AO19) -> 1348.8121 | AB19: =MIN(S19/Entradas!$C$29,AU19) -> 2248.0202 | AD19: =DEGREES(ATAN(TAN(RADIANS(G19))/Entradas!$D$27)) -> 22.615613 | AE19: =TAN(RADIANS(45+AD19/2))^2 -> 2.2496382 | AF19: =EXP(PI()*TAN(RADIANS(AD19)))*AE19 -> 8.3269124 | AG19: =(AF19-1)/TAN(RADIANS(AD19)) -> 17.588266 | AH19: =(AF19-1)*TAN(RADIANS(1.4*AD19)) -> 4.518458 | AI19: =F19/Entradas!$D$27*AG19*(1+0.2*AE19*Entradas!$C$22)*(1+0.2*SQRT(AE19)*Entradas!$C$18/D19)+J19*AF19*(1+0.1*AE19*Entradas!$C$22)*(1+0.1*SQRT(AE19)*Entradas!$C$18/D19)+0.5*I19*D19*AH19*(1+0.1*AE19*Entradas!$C$22)*(1+0.1*SQRT(AE19)*Entradas!$C$18/D19) -> 960.77225 | AJ19: =DEGREES(ATAN(TAN(RADIANS(G19))/Entradas!$D$28)) -> 26.56026 | AK19: =TAN(RADIANS(45+AJ19/2))^2 -> 2.6175445 | AL19: =EXP(PI()*TAN(RADIANS(AJ19)))*AK19 -> 12.587505 | AM19: =(AL19-1)/TAN(RADIANS(AJ19)) -> 23.179855 | AN19: =(AL19-1)*TAN(RADIANS(1.4*AJ19)) -> 8.790412 | AO19: =F19/Entradas!$D$28*AM19*(1+0.2*AK19*Entradas!$C$22)*(1+0.2*SQRT(AK19)*Entradas!$C$18/D19)+J19*AL19*(1+0.1*AK19*Entradas!$C$22)*(1+0.1*SQRT(AK19)*Entradas!$C$18/D19)+0.5*I19*D19*AN19*(1+0.1*AK19*Entradas!$C$22)*(1+0.1*SQRT(AK19)*Entradas!$C$18/D19) -> 1600.8491 | AP19: =DEGREES(ATAN(TAN(RADIANS(G19))/Entradas!$D$29)) -> 29.599306 | AQ19: =TAN(RADIANS(45+AP19/2))^2 -> 2.9520329 | AR19: =EXP(PI()*TAN(RADIANS(AP19)))*AQ19 -> 17.586239 | AS19: =(AR19-1)/TAN(RADIANS(AP19)) -> 29.197885 | AT19: =(AR19-1)*TAN(RADIANS(1.4*AP19)) -> 14.642829 | AU19: =F19/Entradas!$D$29*AS19*(1+0.2*AQ19*Entradas!$C$22)*(1+0.2*SQRT(AQ19)*Entradas!$C$18/D19)+J19*AR19*(1+0.1*AQ19*Entradas!$C$22)*(1+0.1*SQRT(AQ19)*Entradas!$C$18/D19)+0.5*I19*D19*AT19*(1+0.1*AQ19*Entradas!$C$22)*(1+0.1*SQRT(AQ19)*Entradas!$C$18/D19) -> 2409.3393
A20: S1 | B20: Oriental (Ibagué) | C20: Máximo | D20: 2 | E20: NF profundo | F20: =Entradas!G5 -> 29 | G20: =Entradas!G6 -> 32 | H20: =Entradas!G7 -> 18 | I20: =IF(E20="NF en la base",H20-Entradas!$C$19,H20) -> 18 | J20: =H20*Entradas!$C$18 -> 27 | K20: =TAN(RADIANS(45+G20/2))^2 -> 3.2545883 | L20: =EXP(PI()*TAN(RADIANS(G20)))*K20 -> 23.176776 | M20: =(L20-1)/TAN(RADIANS(G20)) -> 35.490261 | N20: =(L20-1)*TAN(RADIANS(1.4*G20)) -> 22.022491 | O20: =1+0.2*K20*Entradas!$C$22 -> 1.6509177 | P20: =1+0.1*K20*Entradas!$C$22 -> 1.3254588 | Q20: =1+0.2*SQRT(K20)*Entradas!$C$18/D20 -> 1.2706072 | R20: =1+0.1*SQRT(K20)*Entradas!$C$18/D20 -> 1.1353036 | S20: =F20*M20*O20*Q20+J20*L20*P20*R20+0.5*I20*D20*N20*P20*R20 -> 3697.1278 | T20: =S20/Entradas!$C$27 -> 1232.3759 | U20: =AI20 -> 1021.1781 | V20: =MIN(T20,U20) -> 1021.1781 | W20: =Entradas!G8 -> 19152 | X20: =Entradas!$C$20*W20/(Entradas!$C$21*D20*(1-Entradas!G9^2))+J20 -> 298.37042 | Y20: =MIN(V20,X20) -> 298.37042 | Z20: =IF(X20<V20,"Asentamiento",IF(T20<=U20,"Falla (FSICP)","Falla (FSB directo)")) -> Asentamiento | AA20: =MIN(S20/Entradas!$C$28,AO20) -> 1478.8511 | AB20: =MIN(S20/Entradas!$C$29,AU20) -> 2464.7519 | AD20: =DEGREES(ATAN(TAN(RADIANS(G20))/Entradas!$D$27)) -> 22.615613 | AE20: =TAN(RADIANS(45+AD20/2))^2 -> 2.2496382 | AF20: =EXP(PI()*TAN(RADIANS(AD20)))*AE20 -> 8.3269124 | AG20: =(AF20-1)/TAN(RADIANS(AD20)) -> 17.588266 | AH20: =(AF20-1)*TAN(RADIANS(1.4*AD20)) -> 4.518458 | AI20: =F20/Entradas!$D$27*AG20*(1+0.2*AE20*Entradas!$C$22)*(1+0.2*SQRT(AE20)*Entradas!$C$18/D20)+J20*AF20*(1+0.1*AE20*Entradas!$C$22)*(1+0.1*SQRT(AE20)*Entradas!$C$18/D20)+0.5*I20*D20*AH20*(1+0.1*AE20*Entradas!$C$22)*(1+0.1*SQRT(AE20)*Entradas!$C$18/D20) -> 1021.1781 | AJ20: =DEGREES(ATAN(TAN(RADIANS(G20))/Entradas!$D$28)) -> 26.56026 | AK20: =TAN(RADIANS(45+AJ20/2))^2 -> 2.6175445 | AL20: =EXP(PI()*TAN(RADIANS(AJ20)))*AK20 -> 12.587505 | AM20: =(AL20-1)/TAN(RADIANS(AJ20)) -> 23.179855 | AN20: =(AL20-1)*TAN(RADIANS(1.4*AJ20)) -> 8.790412 | AO20: =F20/Entradas!$D$28*AM20*(1+0.2*AK20*Entradas!$C$22)*(1+0.2*SQRT(AK20)*Entradas!$C$18/D20)+J20*AL20*(1+0.1*AK20*Entradas!$C$22)*(1+0.1*SQRT(AK20)*Entradas!$C$18/D20)+0.5*I20*D20*AN20*(1+0.1*AK20*Entradas!$C$22)*(1+0.1*SQRT(AK20)*Entradas!$C$18/D20) -> 1722.8578 | AP20: =DEGREES(ATAN(TAN(RADIANS(G20))/Entradas!$D$29)) -> 29.599306 | AQ20: =TAN(RADIANS(45+AP20/2))^2 -> 2.9520329 | AR20: =EXP(PI()*TAN(RADIANS(AP20)))*AQ20 -> 17.586239 | AS20: =(AR20-1)/TAN(RADIANS(AP20)) -> 29.197885 | AT20: =(AR20-1)*TAN(RADIANS(1.4*AP20)) -> 14.642829 | AU20: =F20/Entradas!$D$29*AS20*(1+0.2*AQ20*Entradas!$C$22)*(1+0.2*SQRT(AQ20)*Entradas!$C$18/D20)+J20*AR20*(1+0.1*AQ20*Entradas!$C$22)*(1+0.1*SQRT(AQ20)*Entradas!$C$18/D20)+0.5*I20*D20*AT20*(1+0.1*AQ20*Entradas!$C$22)*(1+0.1*SQRT(AQ20)*Entradas!$C$18/D20) -> 2619.365
A21: S1 | B21: Oriental (Ibagué) | C21: Máximo | D21: 3 | E21: NF en la base | F21: =Entradas!G5 -> 29 | G21: =Entradas!G6 -> 32 | H21: =Entradas!G7 -> 18 | I21: =IF(E21="NF en la base",H21-Entradas!$C$19,H21) -> 8.19 | J21: =H21*Entradas!$C$18 -> 27 | K21: =TAN(RADIANS(45+G21/2))^2 -> 3.2545883 | L21: =EXP(PI()*TAN(RADIANS(G21)))*K21 -> 23.176776 | M21: =(L21-1)/TAN(RADIANS(G21)) -> 35.490261 | N21: =(L21-1)*TAN(RADIANS(1.4*G21)) -> 22.022491 | O21: =1+0.2*K21*Entradas!$C$22 -> 1.6509177 | P21: =1+0.1*K21*Entradas!$C$22 -> 1.3254588 | Q21: =1+0.2*SQRT(K21)*Entradas!$C$18/D21 -> 1.1804048 | R21: =1+0.1*SQRT(K21)*Entradas!$C$18/D21 -> 1.0902024 | S21: =F21*M21*O21*Q21+J21*L21*P21*R21+0.5*I21*D21*N21*P21*R21 -> 3300.8867 | T21: =S21/Entradas!$C$27 -> 1100.2956 | U21: =AI21 -> 936.13651 | V21: =MIN(T21,U21) -> 936.13651 | W21: =Entradas!G8 -> 19152 | X21: =Entradas!$C$20*W21/(Entradas!$C$21*D21*(1-Entradas!G9^2))+J21 -> 207.91361 | Y21: =MIN(V21,X21) -> 207.91361 | Z21: =IF(X21<V21,"Asentamiento",IF(T21<=U21,"Falla (FSICP)","Falla (FSB directo)")) -> Asentamiento | AA21: =MIN(S21/Entradas!$C$28,AO21) -> 1320.3547 | AB21: =MIN(S21/Entradas!$C$29,AU21) -> 2200.5911 | AD21: =DEGREES(ATAN(TAN(RADIANS(G21))/Entradas!$D$27)) -> 22.615613 | AE21: =TAN(RADIANS(45+AD21/2))^2 -> 2.2496382 | AF21: =EXP(PI()*TAN(RADIANS(AD21)))*AE21 -> 8.3269124 | AG21: =(AF21-1)/TAN(RADIANS(AD21)) -> 17.588266 | AH21: =(AF21-1)*TAN(RADIANS(1.4*AD21)) -> 4.518458 | AI21: =F21/Entradas!$D$27*AG21*(1+0.2*AE21*Entradas!$C$22)*(1+0.2*SQRT(AE21)*Entradas!$C$18/D21)+J21*AF21*(1+0.1*AE21*Entradas!$C$22)*(1+0.1*SQRT(AE21)*Entradas!$C$18/D21)+0.5*I21*D21*AH21*(1+0.1*AE21*Entradas!$C$22)*(1+0.1*SQRT(AE21)*Entradas!$C$18/D21) -> 936.13651 | AJ21: =DEGREES(ATAN(TAN(RADIANS(G21))/Entradas!$D$28)) -> 26.56026 | AK21: =TAN(RADIANS(45+AJ21/2))^2 -> 2.6175445 | AL21: =EXP(PI()*TAN(RADIANS(AJ21)))*AK21 -> 12.587505 | AM21: =(AL21-1)/TAN(RADIANS(AJ21)) -> 23.179855 | AN21: =(AL21-1)*TAN(RADIANS(1.4*AJ21)) -> 8.790412 | AO21: =F21/Entradas!$D$28*AM21*(1+0.2*AK21*Entradas!$C$22)*(1+0.2*SQRT(AK21)*Entradas!$C$18/D21)+J21*AL21*(1+0.1*AK21*Entradas!$C$22)*(1+0.1*SQRT(AK21)*Entradas!$C$18/D21)+0.5*I21*D21*AN21*(1+0.1*AK21*Entradas!$C$22)*(1+0.1*SQRT(AK21)*Entradas!$C$18/D21) -> 1562.6468 | AP21: =DEGREES(ATAN(TAN(RADIANS(G21))/Entradas!$D$29)) -> 29.599306 | AQ21: =TAN(RADIANS(45+AP21/2))^2 -> 2.9520329 | AR21: =EXP(PI()*TAN(RADIANS(AP21)))*AQ21 -> 17.586239 | AS21: =(AR21-1)/TAN(RADIANS(AP21)) -> 29.197885 | AT21: =(AR21-1)*TAN(RADIANS(1.4*AP21)) -> 14.642829 | AU21: =F21/Entradas!$D$29*AS21*(1+0.2*AQ21*Entradas!$C$22)*(1+0.2*SQRT(AQ21)*Entradas!$C$18/D21)+J21*AR21*(1+0.1*AQ21*Entradas!$C$22)*(1+0.1*SQRT(AQ21)*Entradas!$C$18/D21)+0.5*I21*D21*AT21*(1+0.1*AQ21*Entradas!$C$22)*(1+0.1*SQRT(AQ21)*Entradas!$C$18/D21) -> 2355.4154
