Workbook

Sheet 1. Metodo
A1: Matriz de aforos clasificada - OE 5, Actividad 2
A2: Clasificacion vehicular del TPDA y depuracion del flujo de carga pesada | Semillero GEOPAV | Corredor Ibague - Calarca, Ruta Nacional 40
A5: MARCAS DE ORIGEN
A6: F | B6: Dato tomado de una fuente externa, citada.
A7: CP | B7: Calculo propio del semillero, reproducible por la formula de la celda.
A8: H | B8: Hipotesis adoptada. Celda con fondo amarillo y texto azul.
A10: FUENTES
A11: Serie historica TPD 1997-2018 | B11: INVIAS, idFile=30450. Extraida por Scripts/extraccion_TPD_INVIAS.py [F]
A12: Serie historica TPD 2019 | B12: INVIAS, idFile=1678. Peaje Cajamarca, PR 24+020 [F]
A13: Trafico Vehicular ANI | B13: datos.gov.co 8yi9-t44c. Peaje Cocora, K 13+750 [F]
A15: HOMOLOGACION DE CLASES [H]
A16: Livianos | B16: Peajes: categoria I. Serie por estacion: 'autos'.
A17: Intermedios | B17: Peajes: categoria II (buses y camion de 2 ejes). Serie por estacion: 'buses'.
A18: Carga pesada | B18: Peajes: categorias III a VII (3 o mas ejes). Serie por estacion: 'camiones'.
A20: LIMITACION DE LA HOMOLOGACION
B21: La serie por estacion publica solo tres porcentajes (autos-buses-camiones) y su clase
B22: 'camiones' INCLUYE los de dos ejes, que en el peaje caen en categoria II. Por eso la
B23: participacion de carga pesada de la serie por estacion es sistematicamente MAYOR que la
B24: del peaje. Las dos lecturas se publican por separado y no se promedian.
A26: ADVERTENCIA - TRES PUNTOS DE MEDICION DISTINTOS [F]
A27: Estacion 244 INVIAS | B27: Aforo de tramo Calarca - Cajamarca, 45 km. Es el paso de La Linea.
A28: Peaje Cajamarca | B28: PR 24+020 carretera Armenia - Ibague. Administra INVIAS.
A29: Peaje Cocora | B29: K 13+750 Segunda Calzada Ibague - Cajamarca. Administra la concesion APP GICA (ANI).
B30: Cocora y Cajamarca estan separados unos 10 km. Cocora, mas abajo, capta trafico local que
B31: no sube al paso. Las series NO se empalman en una sola linea de tiempo: cada punto de
B32: medicion se reporta por separado y la comparacion entre ellos se declara como tal.
A34: HITO QUE PARTE LA SERIE [F]
B35: El Tunel de La Linea entro en operacion el 4 de septiembre de 2020, con 8,6 km. Todo lo
B36: anterior a esa fecha describe un corredor distinto del actual.

Sheet 2. Serie INVIAS estacion
A1: Serie historica de TPD por estacion de aforo - INVIAS 1997-2018
A2: Columnas A-L: dato de la fuente [F]. Columnas M-P: clasificacion [CP], calculadas por formula.
A4: Estacion | B4: Depto | C4: Sector | D4: Codigo via | E4: L (km) | F4: En corredor | G4: Anio | H4: TPD total | I4: % autos | J4: % buses | K4: % camiones | L4: TPD livianos | M4: TPD intermedios | N4: TPD carga pesada | O4: Participacion pesada
A5: 243 | B5: TOLIMA | C5: CAJAMARCA-IBAGUE | E5: 29 | F5: Si | G5: 1997 | H5: 3803 | I5: 42 | J5: 6 | K5: 52 | L5: =IF(I5="","",ROUND($H5*I5/100,0)) -> 1597 | M5: =IF(J5="","",ROUND($H5*J5/100,0)) -> 228 | N5: =IF(K5="","",ROUND($H5*K5/100,0)) -> 1978 | O5: =IF(K5="","",K5/100) -> 0.52
A6: 243 | B6: TOLIMA | C6: CAJAMARCA-IBAGUE | E6: 29 | F6: Si | G6: 1998 | H6: 3877 | I6: 42 | J6: 7 | K6: 51 | L6: =IF(I6="","",ROUND($H6*I6/100,0)) -> 1628 | M6: =IF(J6="","",ROUND($H6*J6/100,0)) -> 271 | N6: =IF(K6="","",ROUND($H6*K6/100,0)) -> 1977 | O6: =IF(K6="","",K6/100) -> 0.51
A7: 243 | B7: TOLIMA | C7: CAJAMARCA-IBAGUE | E7: 29 | F7: Si | G7: 1999 | H7: 3449 | I7: 30 | J7: 7 | K7: 63 | L7: =IF(I7="","",ROUND($H7*I7/100,0)) -> 1035 | M7: =IF(J7="","",ROUND($H7*J7/100,0)) -> 241 | N7: =IF(K7="","",ROUND($H7*K7/100,0)) -> 2173 | O7: =IF(K7="","",K7/100) -> 0.63
A8: 243 | B8: TOLIMA | C8: CAJAMARCA-IBAGUE | E8: 29 | F8: Si | G8: 2000 | H8: 3579 | I8: 37 | J8: 8 | K8: 55 | L8: =IF(I8="","",ROUND($H8*I8/100,0)) -> 1324 | M8: =IF(J8="","",ROUND($H8*J8/100,0)) -> 286 | N8: =IF(K8="","",ROUND($H8*K8/100,0)) -> 1968 | O8: =IF(K8="","",K8/100) -> 0.55
A9: 243 | B9: TOLIMA | C9: CAJAMARCA-IBAGUE | E9: 29 | F9: Si | G9: 2001 | H9: 4027 | I9: 35 | J9: 9 | K9: 56 | L9: =IF(I9="","",ROUND($H9*I9/100,0)) -> 1409 | M9: =IF(J9="","",ROUND($H9*J9/100,0)) -> 362 | N9: =IF(K9="","",ROUND($H9*K9/100,0)) -> 2255 | O9: =IF(K9="","",K9/100) -> 0.56
A10: 243 | B10: TOLIMA | C10: CAJAMARCA-IBAGUE | E10: 29 | F10: Si | G10: 2002 | H10: 3597 | I10: 32 | J10: 11 | K10: 57 | L10: =IF(I10="","",ROUND($H10*I10/100,0)) -> 1151 | M10: =IF(J10="","",ROUND($H10*J10/100,0)) -> 396 | N10: =IF(K10="","",ROUND($H10*K10/100,0)) -> 2050 | O10: =IF(K10="","",K10/100) -> 0.57
A11: 243 | B11: TOLIMA | C11: CAJAMARCA-IBAGUE | E11: 29 | F11: Si | G11: 2003 | H11: 4019 | I11: 31 | J11: 13 | K11: 56 | L11: =IF(I11="","",ROUND($H11*I11/100,0)) -> 1246 | M11: =IF(J11="","",ROUND($H11*J11/100,0)) -> 522 | N11: =IF(K11="","",ROUND($H11*K11/100,0)) -> 2251 | O11: =IF(K11="","",K11/100) -> 0.56
A12: 243 | B12: TOLIMA | C12: CAJAMARCA-IBAGUE | E12: 29 | F12: Si | G12: 2004 | H12: 4567 | I12: 29 | J12: 13 | K12: 58 | L12: =IF(I12="","",ROUND($H12*I12/100,0)) -> 1324 | M12: =IF(J12="","",ROUND($H12*J12/100,0)) -> 594 | N12: =IF(K12="","",ROUND($H12*K12/100,0)) -> 2649 | O12: =IF(K12="","",K12/100) -> 0.58
A13: 243 | B13: TOLIMA | C13: CAJAMARCA-IBAGUE | E13: 29 | F13: Si | G13: 2005 | H13: 4961 | I13: 32 | J13: 11 | K13: 57 | L13: =IF(I13="","",ROUND($H13*I13/100,0)) -> 1588 | M13: =IF(J13="","",ROUND($H13*J13/100,0)) -> 546 | N13: =IF(K13="","",ROUND($H13*K13/100,0)) -> 2828 | O13: =IF(K13="","",K13/100) -> 0.57
A14: 243 | B14: TOLIMA | C14: CAJAMARCA-IBAGUE | E14: 29 | F14: Si | G14: 2006 | H14: 5206 | I14: 32 | J14: 11 | K14: 57 | L14: =IF(I14="","",ROUND($H14*I14/100,0)) -> 1666 | M14: =IF(J14="","",ROUND($H14*J14/100,0)) -> 573 | N14: =IF(K14="","",ROUND($H14*K14/100,0)) -> 2967 | O14: =IF(K14="","",K14/100) -> 0.57
A15: 243 | B15: TOLIMA | C15: CAJAMARCA-IBAGUE | E15: 29 | F15: Si | G15: 2007 | H15: 5475 | I15: 35 | J15: 11 | K15: 54 | L15: =IF(I15="","",ROUND($H15*I15/100,0)) -> 1916 | M15: =IF(J15="","",ROUND($H15*J15/100,0)) -> 602 | N15: =IF(K15="","",ROUND($H15*K15/100,0)) -> 2957 | O15: =IF(K15="","",K15/100) -> 0.54
A16: 243 | B16: TOLIMA | C16: CAJAMARCA-IBAGUE | E16: 29 | F16: Si | G16: 2008 | H16: 5326 | I16: 35 | J16: 12 | K16: 53 | L16: =IF(I16="","",ROUND($H16*I16/100,0)) -> 1864 | M16: =IF(J16="","",ROUND($H16*J16/100,0)) -> 639 | N16: =IF(K16="","",ROUND($H16*K16/100,0)) -> 2823 | O16: =IF(K16="","",K16/100) -> 0.53
... A24: 243 | B24: TOLIMA | C24: CAJAMARCA-IBAGUE | E24: 29 | F24: Si | G24: 2017 | H24: 7080 | I24: 41 | J24: 9 | K24: 50 | L24: =IF(I24="","",ROUND($H24*I24/100,0)) -> 2903 | M24: =IF(J24="","",ROUND($H24*J24/100,0)) -> 637 | N24: =IF(K24="","",ROUND($H24*K24/100,0)) -> 3540 | O24: =IF(K24="","",K24/100) -> 0.5
A25: 244 | B25: QUINDIO | C25: CALARCA - CAJAMARCA | D25: 4003 | E25: 45 | F25: Si | G25: 1997 | H25: 3194 | I25: 32 | J25: 8 | K25: 60 | L25: =IF(I25="","",ROUND($H25*I25/100,0)) -> 1022 | M25: =IF(J25="","",ROUND($H25*J25/100,0)) -> 256 | N25: =IF(K25="","",ROUND($H25*K25/100,0)) -> 1916 | O25: =IF(K25="","",K25/100) -> 0.6
A26: 244 | B26: QUINDIO | C26: CALARCA - CAJAMARCA | D26: 4003 | E26: 45 | F26: Si | G26: 1998 | H26: 3546 | I26: 30 | J26: 7 | K26: 63 | L26: =IF(I26="","",ROUND($H26*I26/100,0)) -> 1064 | M26: =IF(J26="","",ROUND($H26*J26/100,0)) -> 248 | N26: =IF(K26="","",ROUND($H26*K26/100,0)) -> 2234 | O26: =IF(K26="","",K26/100) -> 0.63
A27: 244 | B27: QUINDIO | C27: CALARCA - CAJAMARCA | D27: 4003 | E27: 45 | F27: Si | G27: 1999 | H27: 2932 | I27: 31 | J27: 6 | K27: 63 | L27: =IF(I27="","",ROUND($H27*I27/100,0)) -> 909 | M27: =IF(J27="","",ROUND($H27*J27/100,0)) -> 176 | N27: =IF(K27="","",ROUND($H27*K27/100,0)) -> 1847 | O27: =IF(K27="","",K27/100) -> 0.63
A28: 244 | B28: QUINDIO | C28: CALARCA - CAJAMARCA | D28: 4003 | E28: 45 | F28: Si | G28: 2000 | H28: 3147 | I28: 30 | J28: 8 | K28: 62 | L28: =IF(I28="","",ROUND($H28*I28/100,0)) -> 944 | M28: =IF(J28="","",ROUND($H28*J28/100,0)) -> 252 | N28: =IF(K28="","",ROUND($H28*K28/100,0)) -> 1951 | O28: =IF(K28="","",K28/100) -> 0.62
A29: 244 | B29: QUINDIO | C29: CALARCA - CAJAMARCA | D29: 4003 | E29: 45 | F29: Si | G29: 2001 | H29: 3093 | I29: 29 | J29: 8 | K29: 63 | L29: =IF(I29="","",ROUND($H29*I29/100,0)) -> 897 | M29: =IF(J29="","",ROUND($H29*J29/100,0)) -> 247 | N29: =IF(K29="","",ROUND($H29*K29/100,0)) -> 1949 | O29: =IF(K29="","",K29/100) -> 0.63
A30: 244 | B30: QUINDIO | C30: CALARCA - CAJAMARCA | D30: 4003 | E30: 45 | F30: Si | G30: 2002 | H30: 3374 | I30: 20 | J30: 12 | K30: 68 | L30: =IF(I30="","",ROUND($H30*I30/100,0)) -> 675 | M30: =IF(J30="","",ROUND($H30*J30/100,0)) -> 405 | N30: =IF(K30="","",ROUND($H30*K30/100,0)) -> 2294 | O30: =IF(K30="","",K30/100) -> 0.68
A31: 244 | B31: QUINDIO | C31: CALARCA - CAJAMARCA | D31: 4003 | E31: 45 | F31: Si | G31: 2003 | H31: 3412 | I31: 30 | J31: 12 | K31: 58 | L31: =IF(I31="","",ROUND($H31*I31/100,0)) -> 1024 | M31: =IF(J31="","",ROUND($H31*J31/100,0)) -> 409 | N31: =IF(K31="","",ROUND($H31*K31/100,0)) -> 1979 | O31: =IF(K31="","",K31/100) -> 0.58
A32: 244 | B32: QUINDIO | C32: CALARCA - CAJAMARCA | D32: 4003 | E32: 45 | F32: Si | G32: 2004 | H32: 3600 | I32: 31 | J32: 10 | K32: 59 | L32: =IF(I32="","",ROUND($H32*I32/100,0)) -> 1116 | M32: =IF(J32="","",ROUND($H32*J32/100,0)) -> 360 | N32: =IF(K32="","",ROUND($H32*K32/100,0)) -> 2124 | O32: =IF(K32="","",K32/100) -> 0.59
A33: 244 | B33: QUINDIO | C33: CALARCA - CAJAMARCA | D33: 4003 | E33: 45 | F33: Si | G33: 2005 | H33: 4670 | I33: 23 | J33: 14 | K33: 63 | L33: =IF(I33="","",ROUND($H33*I33/100,0)) -> 1074 | M33: =IF(J33="","",ROUND($H33*J33/100,0)) -> 654 | N33: =IF(K33="","",ROUND($H33*K33/100,0)) -> 2942 | O33: =IF(K33="","",K33/100) -> 0.63
A34: 244 | B34: QUINDIO | C34: CALARCA - CAJAMARCA | D34: 4003 | E34: 45 | F34: Si | G34: 2006 | H34: 4498 | I34: 24 | J34: 11 | K34: 65 | L34: =IF(I34="","",ROUND($H34*I34/100,0)) -> 1080 | M34: =IF(J34="","",ROUND($H34*J34/100,0)) -> 495 | N34: =IF(K34="","",ROUND($H34*K34/100,0)) -> 2924 | O34: =IF(K34="","",K34/100) -> 0.65
A35: 244 | B35: QUINDIO | C35: CALARCA - CAJAMARCA | D35: 4003 | E35: 45 | F35: Si | G35: 2007 | H35: 4898 | I35: 32 | J35: 12 | K35: 56 | L35: =IF(I35="","",ROUND($H35*I35/100,0)) -> 1567 | M35: =IF(J35="","",ROUND($H35*J35/100,0)) -> 588 | N35: =IF(K35="","",ROUND($H35*K35/100,0)) -> 2743 | O35: =IF(K35="","",K35/100) -> 0.56
A36: 244 | B36: QUINDIO | C36: CALARCA - CAJAMARCA | D36: 4003 | E36: 45 | F36: Si | G36: 2008 | H36: 4773 | I36: 26 | J36: 16 | K36: 58 | L36: =IF(I36="","",ROUND($H36*I36/100,0)) -> 1241 | M36: =IF(J36="","",ROUND($H36*J36/100,0)) -> 764 | N36: =IF(K36="","",ROUND($H36*K36/100,0)) -> 2768 | O36: =IF(K36="","",K36/100) -> 0.58
... A50: 245 | B50: QUINDIO | C50: ARMENIA - CALARCA | D50: 4003 | E50: 5 | F50: No | G50: 2002 | H50: 12434 | I50: 84 | J50: 7 | K50: 9 | L50: =IF(I50="","",ROUND($H50*I50/100,0)) -> 10445 | M50: =IF(J50="","",ROUND($H50*J50/100,0)) -> 870 | N50: =IF(K50="","",ROUND($H50*K50/100,0)) -> 1119 | O50: =IF(K50="","",K50/100) -> 0.09
A51: 245 | B51: QUINDIO | C51: ARMENIA - CALARCA | D51: 4003 | E51: 5 | F51: No | G51: 2003 | H51: 14053 | L51: =IF(I51="","",ROUND($H51*I51/100,0)) | M51: =IF(J51="","",ROUND($H51*J51/100,0)) | N51: =IF(K51="","",ROUND($H51*K51/100,0)) | O51: =IF(K51="","",K51/100)
A52: 245 | B52: QUINDIO | C52: ARMENIA - CALARCA | D52: 4003 | E52: 5 | F52: No | G52: 2004 | H52: 11276 | I52: 72 | J52: 16 | K52: 12 | L52: =IF(I52="","",ROUND($H52*I52/100,0)) -> 8119 | M52: =IF(J52="","",ROUND($H52*J52/100,0)) -> 1804 | N52: =IF(K52="","",ROUND($H52*K52/100,0)) -> 1353 | O52: =IF(K52="","",K52/100) -> 0.12
A53: 245 | B53: QUINDIO | C53: ARMENIA - CALARCA | D53: 4003 | E53: 5 | F53: No | G53: 2005 | H53: 11474 | I53: 76 | J53: 15 | K53: 9 | L53: =IF(I53="","",ROUND($H53*I53/100,0)) -> 8720 | M53: =IF(J53="","",ROUND($H53*J53/100,0)) -> 1721 | N53: =IF(K53="","",ROUND($H53*K53/100,0)) -> 1033 | O53: =IF(K53="","",K53/100) -> 0.09
A54: 245 | B54: QUINDIO | C54: ARMENIA - CALARCA | D54: 4003 | E54: 5 | F54: No | G54: 2006 | H54: 9925 | I54: 76 | J54: 13 | K54: 11 | L54: =IF(I54="","",ROUND($H54*I54/100,0)) -> 7543 | M54: =IF(J54="","",ROUND($H54*J54/100,0)) -> 1290 | N54: =IF(K54="","",ROUND($H54*K54/100,0)) -> 1092 | O54: =IF(K54="","",K54/100) -> 0.11
A55: 245 | B55: QUINDIO | C55: ARMENIA - CALARCA | D55: 4003 | E55: 5 | F55: No | G55: 2007 | H55: 16348 | I55: 74 | J55: 16 | K55: 10 | L55: =IF(I55="","",ROUND($H55*I55/100,0)) -> 12098 | M55: =IF(J55="","",ROUND($H55*J55/100,0)) -> 2616 | N55: =IF(K55="","",ROUND($H55*K55/100,0)) -> 1635 | O55: =IF(K55="","",K55/100) -> 0.1
A56: 245 | B56: QUINDIO | C56: ARMENIA - CALARCA | D56: 4003 | E56: 5 | F56: No | G56: 2008 | H56: 11412 | I56: 75 | J56: 16 | K56: 9 | L56: =IF(I56="","",ROUND($H56*I56/100,0)) -> 8559 | M56: =IF(J56="","",ROUND($H56*J56/100,0)) -> 1826 | N56: =IF(K56="","",ROUND($H56*K56/100,0)) -> 1027 | O56: =IF(K56="","",K56/100) -> 0.09
A57: 245 | B57: QUINDIO | C57: ARMENIA - CALARCA | D57: 4003 | E57: 5 | F57: No | G57: 2009 | H57: 10821 | I57: 82 | J57: 10 | K57: 8 | L57: =IF(I57="","",ROUND($H57*I57/100,0)) -> 8873 | M57: =IF(J57="","",ROUND($H57*J57/100,0)) -> 1082 | N57: =IF(K57="","",ROUND($H57*K57/100,0)) -> 866 | O57: =IF(K57="","",K57/100) -> 0.08
A58: 245 | B58: QUINDIO | C58: ARMENIA - CALARCA | D58: 4003 | E58: 5 | F58: No | G58: 2010 | H58: 11283 | I58: 76 | J58: 17 | K58: 7 | L58: =IF(I58="","",ROUND($H58*I58/100,0)) -> 8575 | M58: =IF(J58="","",ROUND($H58*J58/100,0)) -> 1918 | N58: =IF(K58="","",ROUND($H58*K58/100,0)) -> 790 | O58: =IF(K58="","",K58/100) -> 0.07
A59: 245 | B59: QUINDIO | C59: ARMENIA - CALARCA | D59: 4003 | E59: 5 | F59: No | G59: 2011 | H59: 12347 | I59: 74 | J59: 19 | K59: 7 | L59: =IF(I59="","",ROUND($H59*I59/100,0)) -> 9137 | M59: =IF(J59="","",ROUND($H59*J59/100,0)) -> 2346 | N59: =IF(K59="","",ROUND($H59*K59/100,0)) -> 864 | O59: =IF(K59="","",K59/100) -> 0.07
A60: 245 | B60: QUINDIO | C60: ARMENIA - CALARCA | D60: 4003 | E60: 5 | F60: No | G60: 2012 | H60: 10679 | I60: 71 | J60: 20 | K60: 9 | L60: =IF(I60="","",ROUND($H60*I60/100,0)) -> 7582 | M60: =IF(J60="","",ROUND($H60*J60/100,0)) -> 2136 | N60: =IF(K60="","",ROUND($H60*K60/100,0)) -> 961 | O60: =IF(K60="","",K60/100) -> 0.09
A61: 245 | B61: QUINDIO | C61: ARMENIA - CALARCA | D61: 4003 | E61: 5 | F61: No | G61: 2013 | H61: 10976 | I61: 68 | J61: 24 | K61: 8 | L61: =IF(I61="","",ROUND($H61*I61/100,0)) -> 7464 | M61: =IF(J61="","",ROUND($H61*J61/100,0)) -> 2634 | N61: =IF(K61="","",ROUND($H61*K61/100,0)) -> 878 | O61: =IF(K61="","",K61/100) -> 0.08
...

Sheet 3. Peaje Cajamarca 2019
A1: Aforo mensual por categoria tarifaria - Peaje Cajamarca (INVIAS), 2019
A2: Columnas A-F: dato de la fuente [F]. Columnas G-J: clasificacion [CP].
A4: Mes | B4: Dias | C4: Total | D4: Cat I livianos | E4: Cat II intermedios | F4: Cat III+ carga pesada | G4: TPD total | H4: TPD livianos | I4: TPD carga pesada | J4: Participacion pesada
A5: 2019-01 | B5: 31 | C5: =SUM(D5:F5) -> 242199 | D5: 122012 | E5: 59954 | F5: 60233 | G5: =ROUND(C5/B5,0) -> 7813 | H5: =ROUND(D5/B5,0) -> 3936 | I5: =ROUND(F5/B5,0) -> 1943 | J5: =F5/C5 -> 0.24869219
A6: 2019-02 | B6: 28 | C6: =SUM(D6:F6) -> 157619 | D6: 42295 | E6: 55983 | F6: 59341 | G6: =ROUND(C6/B6,0) -> 5629 | H6: =ROUND(D6/B6,0) -> 1511 | I6: =ROUND(F6/B6,0) -> 2119 | J6: =F6/C6 -> 0.3764838
A7: 2019-03 | B7: 31 | C7: =SUM(D7:F7) -> 168022 | D7: 49724 | E7: 59963 | F7: 58335 | G7: =ROUND(C7/B7,0) -> 5420 | H7: =ROUND(D7/B7,0) -> 1604 | I7: =ROUND(F7/B7,0) -> 1882 | J7: =F7/C7 -> 0.34718668
A8: 2019-04 | B8: 30 | C8: =SUM(D8:F8) -> 197595 | D8: 81489 | E8: 59157 | F8: 56949 | G8: =ROUND(C8/B8,0) -> 6587 | H8: =ROUND(D8/B8,0) -> 2716 | I8: =ROUND(F8/B8,0) -> 1898 | J8: =F8/C8 -> 0.28821073
A9: 2019-05 | B9: 31 | C9: =SUM(D9:F9) -> 174712 | D9: 44609 | E9: 64697 | F9: 65406 | G9: =ROUND(C9/B9,0) -> 5636 | H9: =ROUND(D9/B9,0) -> 1439 | I9: =ROUND(F9/B9,0) -> 2110 | J9: =F9/C9 -> 0.37436467
A10: 2019-06 | B10: 30 | C10: =SUM(D10:F10) -> 191348 | D10: 70004 | E10: 60007 | F10: 61337 | G10: =ROUND(C10/B10,0) -> 6378 | H10: =ROUND(D10/B10,0) -> 2333 | I10: =ROUND(F10/B10,0) -> 2045 | J10: =F10/C10 -> 0.32055208
A11: 2019-07 | B11: 31 | C11: =SUM(D11:F11) -> 195836 | D11: 64775 | E11: 63861 | F11: 67200 | G11: =ROUND(C11/B11,0) -> 6317 | H11: =ROUND(D11/B11,0) -> 2090 | I11: =ROUND(F11/B11,0) -> 2168 | J11: =F11/C11 -> 0.34314426
A12: 2019-08 | B12: 31 | C12: =SUM(D12:F12) -> 193454 | D12: 62225 | E12: 64549 | F12: 66680 | G12: =ROUND(C12/B12,0) -> 6240 | H12: =ROUND(D12/B12,0) -> 2007 | I12: =ROUND(F12/B12,0) -> 2151 | J12: =F12/C12 -> 0.34468142
A13: 2019-09 | B13: 30 | C13: =SUM(D13:F13) -> 180502 | D13: 48275 | E13: 62857 | F13: 69370 | G13: =ROUND(C13/B13,0) -> 6017 | H13: =ROUND(D13/B13,0) -> 1609 | I13: =ROUND(F13/B13,0) -> 2312 | J13: =F13/C13 -> 0.38431707
A14: 2019-10 | B14: 31 | C14: =SUM(D14:F14) -> 200469 | D14: 64782 | E14: 64749 | F14: 70938 | G14: =ROUND(C14/B14,0) -> 6467 | H14: =ROUND(D14/B14,0) -> 2090 | I14: =ROUND(F14/B14,0) -> 2288 | J14: =F14/C14 -> 0.3538602
A15: 2019-11 | B15: 30 | C15: =SUM(D15:F15) -> 186153 | D15: 59597 | E15: 61854 | F15: 64702 | G15: =ROUND(C15/B15,0) -> 6205 | H15: =ROUND(D15/B15,0) -> 1987 | I15: =ROUND(F15/B15,0) -> 2157 | J15: =F15/C15 -> 0.34757431
A16: 2019-12 | B16: 31 | C16: =SUM(D16:F16) -> 230301 | D16: 104781 | E16: 62370 | F16: 63150 | G16: =ROUND(C16/B16,0) -> 7429 | H16: =ROUND(D16/B16,0) -> 3380 | I16: =ROUND(F16/B16,0) -> 2037 | J16: =F16/C16 -> 0.27420636
A17: AÑO 2019 | B17: =SUM(B5:B16) -> 365 | C17: =SUM(C5:C16) -> 2318210 | D17: =SUM(D5:D16) -> 814568 | E17: =SUM(E5:E16) -> 740001 | F17: =SUM(F5:F16) -> 763641 | G17: =ROUND(C17/B17,0) -> 6351 | H17: =ROUND(D17/B17,0) -> 2232 | I17: =ROUND(F17/B17,0) -> 2092 | J17: =F17/C17 -> 0.32940976

Sheet 4. Peaje Cocora 21-26
A1: Aforo mensual por categoria - Peaje Cocora (concesion APP GICA / ANI), oct 2021 - may 2026
A2: Columnas A-G: dato de la fuente [F]. Columnas H-K: clasificacion [CP].
A4: Mes | B4: Dias | C4: Total | D4: Livianos | E4: Buses (Cat II) | F4: Carga pesada (Cat III+) | G4: Otros | H4: TPD total | I4: TPD livianos | J4: TPD carga pesada | K4: Participacion pesada
A5: 2021-10 | B5: 31 | C5: =SUM(D5:G5) -> 31703 | D5: 13804 | E5: 8535 | F5: 9124 | G5: 240 | H5: =ROUND(C5/B5,0) -> 1023 | I5: =ROUND(D5/B5,0) -> 445 | J5: =ROUND(F5/B5,0) -> 294 | K5: =F5/C5 -> 0.28779611
A6: 2021-11 | B6: 30 | C6: =SUM(D6:G6) -> 80209 | D6: 37660 | E6: 20990 | F6: 20711 | G6: 848 | H6: =ROUND(C6/B6,0) -> 2674 | I6: =ROUND(D6/B6,0) -> 1255 | J6: =ROUND(F6/B6,0) -> 690 | K6: =F6/C6 -> 0.25821292
A7: 2021-12 | B7: 31 | C7: =SUM(D7:G7) -> 126100 | D7: 83155 | E7: 22807 | F7: 19318 | G7: 820 | H7: =ROUND(C7/B7,0) -> 4068 | I7: =ROUND(D7/B7,0) -> 2682 | J7: =ROUND(F7/B7,0) -> 623 | K7: =F7/C7 -> 0.15319588
A8: 2022-01 | B8: 31 | C8: =SUM(D8:G8) -> 99824 | D8: 62264 | E8: 19476 | F8: 18084 | G8: 0 | H8: =ROUND(C8/B8,0) -> 3220 | I8: =ROUND(D8/B8,0) -> 2009 | J8: =ROUND(F8/B8,0) -> 583 | K8: =F8/C8 -> 0.18115884
A9: 2022-02 | B9: 28 | C9: =SUM(D9:G9) -> 61507 | D9: 28454 | E9: 17175 | F9: 15878 | G9: 0 | H9: =ROUND(C9/B9,0) -> 2197 | I9: =ROUND(D9/B9,0) -> 1016 | J9: =ROUND(F9/B9,0) -> 567 | K9: =F9/C9 -> 0.25814948
A10: 2022-03 | B10: 31 | C10: =SUM(D10:G10) -> 70150 | D10: 32573 | E10: 19919 | F10: 17658 | G10: 0 | H10: =ROUND(C10/B10,0) -> 2263 | I10: =ROUND(D10/B10,0) -> 1051 | J10: =ROUND(F10/B10,0) -> 570 | K10: =F10/C10 -> 0.25171775
A11: 2022-04 | B11: 30 | C11: =SUM(D11:G11) -> 85511 | D11: 51133 | E11: 18403 | F11: 15975 | G11: 0 | H11: =ROUND(C11/B11,0) -> 2850 | I11: =ROUND(D11/B11,0) -> 1704 | J11: =ROUND(F11/B11,0) -> 533 | K11: =F11/C11 -> 0.18681807
A12: 2022-05 | B12: 31 | C12: =SUM(D12:G12) -> 47359 | D12: 18540 | E12: 14791 | F12: 14028 | G12: 0 | H12: =ROUND(C12/B12,0) -> 1528 | I12: =ROUND(D12/B12,0) -> 598 | J12: =ROUND(F12/B12,0) -> 453 | K12: =F12/C12 -> 0.29620558
A13: 2022-06 | B13: 30 | C13: =SUM(D13:G13) -> 65482 | D13: 32454 | E13: 17273 | F13: 15755 | G13: 0 | H13: =ROUND(C13/B13,0) -> 2183 | I13: =ROUND(D13/B13,0) -> 1082 | J13: =ROUND(F13/B13,0) -> 525 | K13: =F13/C13 -> 0.24060047
A14: 2022-07 | B14: 31 | C14: =SUM(D14:G14) -> 72729 | D14: 39885 | E14: 17189 | F14: 15655 | G14: 0 | H14: =ROUND(C14/B14,0) -> 2346 | I14: =ROUND(D14/B14,0) -> 1287 | J14: =ROUND(F14/B14,0) -> 505 | K14: =F14/C14 -> 0.21525114
A15: 2022-08 | B15: 31 | C15: =SUM(D15:G15) -> 71289 | D15: 36991 | E15: 18234 | F15: 16064 | G15: 0 | H15: =ROUND(C15/B15,0) -> 2300 | I15: =ROUND(D15/B15,0) -> 1193 | J15: =ROUND(F15/B15,0) -> 518 | K15: =F15/C15 -> 0.22533631
A16: 2022-09 | B16: 30 | C16: =SUM(D16:G16) -> 65877 | D16: 31672 | E16: 18287 | F16: 15918 | G16: 0 | H16: =ROUND(C16/B16,0) -> 2196 | I16: =ROUND(D16/B16,0) -> 1056 | J16: =ROUND(F16/B16,0) -> 531 | K16: =F16/C16 -> 0.24163213
... A60: 2026-05 | B60: 31 | C60: =SUM(D60:G60) -> 131942 | D60: 66756 | E60: 37489 | F60: 27697 | G60: 0 | H60: =ROUND(C60/B60,0) -> 4256 | I60: =ROUND(D60/B60,0) -> 2153 | J60: =ROUND(F60/B60,0) -> 893 | K60: =F60/C60 -> 0.20991799
A61: ULT. 12 MESES | B61: =SUM(B49:B60) -> 365 | C61: =SUM(C49:C60) -> 1808176 | D61: =SUM(D49:D60) -> 1022027 | E61: =SUM(E49:E60) -> 462345 | F61: =SUM(F49:F60) -> 323804 | G61: =SUM(G49:G60) -> 0 | H61: =ROUND(C61/B61,0) -> 4954 | I61: =ROUND(D61/B61,0) -> 2800 | J61: =ROUND(F61/B61,0) -> 887 | K61: =F61/C61 -> 0.1790777
A63: La columna 'Otros' solo tiene valor en oct-dic 2021 y se suma al total sin clasificar: la fuente no dice que categoria es.

Sheet 5. Matriz consolidada
A1: Matriz de aforos clasificada - TPD por clase y punto de medicion
A2: Toda celda de esta hoja es una referencia [CP] a las hojas 2, 3 y 4. No hay ningun numero escrito a mano.
A4: Punto de medicion | B4: Administra | C4: Ubicacion | D4: Periodo | E4: TPD total | F4: TPD livianos | G4: TPD intermedios | H4: TPD carga pesada | I4: Participacion pesada | J4: Base de la clasificacion
A5: Estacion 244 INVIAS | B5: INVIAS | C5: Tramo Calarca - Cajamarca (45 km) - el paso | D5: Media 2015-2018 | E5: =ROUND(AVERAGE('2. Serie INVIAS estacion'!H41:H44),0) -> 6676 | F5: =ROUND(AVERAGE('2. Serie INVIAS estacion'!L41:L44),0) -> 2430 | G5: =ROUND(AVERAGE('2. Serie INVIAS estacion'!M41:M44),0) -> 539 | H5: =ROUND(AVERAGE('2. Serie INVIAS estacion'!N41:N44),0) -> 3708 | I5: =H5/E5 -> 0.55542241 | J5: Composicion % de la fuente; 'camiones' incluye 2 ejes
A6: Estacion 243 INVIAS | B6: INVIAS | C6: Tramo Cajamarca - Ibague (29 km) | D6: Media 2015-2017 | E6: =ROUND(AVERAGE('2. Serie INVIAS estacion'!H22:H24),0) -> 7043 | F6: =ROUND(AVERAGE('2. Serie INVIAS estacion'!L22:L24),0) -> 2588 | G6: =ROUND(AVERAGE('2. Serie INVIAS estacion'!M22:M24),0) -> 634 | H6: =ROUND(AVERAGE('2. Serie INVIAS estacion'!N22:N24),0) -> 3821 | I6: =H6/E6 -> 0.54252449 | J6: Composicion % de la fuente; 'camiones' incluye 2 ejes
A7: Peaje Cajamarca | B7: INVIAS | C7: PR 24+020 Armenia - Ibague | D7: Anio 2019 | E7: ='3. Peaje Cajamarca 2019'!G17 -> 6351 | F7: ='3. Peaje Cajamarca 2019'!H17 -> 2232 | G7: =ROUND('3. Peaje Cajamarca 2019'!E17/'3. Peaje Cajamarca 2019'!B17,0) -> 2027 | H7: ='3. Peaje Cajamarca 2019'!I17 -> 2092 | I7: =H7/E7 -> 0.32939695 | J7: Categoria tarifaria III+ = 3 o mas ejes
A8: Peaje Cocora | B8: APP GICA (ANI) | C8: K 13+750 Segunda Calzada Ibague - Cajamarca | D8: Jun 2025 - may 2026 | E8: ='4. Peaje Cocora 21-26'!H61 -> 4954 | F8: ='4. Peaje Cocora 21-26'!I61 -> 2800 | G8: =ROUND('4. Peaje Cocora 21-26'!E61/'4. Peaje Cocora 21-26'!B61,0) -> 1267 | H8: ='4. Peaje Cocora 21-26'!J61 -> 887 | I8: =H8/E8 -> 0.17904723 | J8: Categoria tarifaria III+ = 3 o mas ejes
A12: COMO SE LEE ESTA MATRIZ
A13: Las filas 5 y 6 miden un TRAMO completo y clasifican por composicion porcentual; las filas 7 y 8 miden un
A14: PUNTO y clasifican por categoria tarifaria. Por eso la participacion de carga pesada de las dos primeras es
A15: mayor: su clase 'camiones' incluye los de dos ejes, que en el peaje son categoria II.
A17: Las cuatro filas NO forman una serie temporal. Son cuatro mediciones distintas del mismo corredor, en puntos
A18: y con criterios distintos. Cualquier comparacion entre filas debe declarar esa diferencia.

Sheet 6. Depuracion pesada
A1: Depuracion del flujo de carga pesada
A2: Aisla el flujo de carga pesada del corredor y estima la porcion captable por la Ferropista. Celdas amarillas = hipotesis editables.
A4: ENTRADAS
A5: Punto de medicion adoptado como proxy del paso | B5: Peaje Cajamarca | C5: H | D5: Peaje Cajamarca (PR 24+020). Esta mas arriba que Cocora y capta mejor lo que sube al paso.
A6: TPD de carga pesada, peaje Cajamarca 2019 | B6: ='5. Matriz consolidada'!H7 -> 2092 | C6: CP | D6: Categoria III+ del aforo de INVIAS.
A7: TPD de carga pesada, peaje Cocora jun25-may26 | B7: ='5. Matriz consolidada'!H8 -> 887 | C7: CP | D7: Categoria III+ del aforo de la ANI.
A8: TPD de carga pesada, estacion 244 media 2015-2018 | B8: ='5. Matriz consolidada'!H5 -> 3708 | C8: CP | D8: Incluye camiones de dos ejes: cota superior.
A9: Captacion prevista de vehiculos grandes | B9: 0.9 | C9: F | D9: Ponencia ARCS/UC Consult, dia. 10. Es cifra del proponente, no auditada.
A10: Longitud del corredor entre portales (km) | B10: 74 | C10: F | D10: INVIAS: 29 km estacion 243 + 45 km estacion 244.
A12: RESULTADOS [CP]
A13: Vehiculos-km diarios de carga pesada en el corredor | B13: =B6*$B$10 -> 154808 | C13: CP | D13: TPD pesada x longitud del corredor.
A14: Vehiculos-km anuales de carga pesada | B14: =B13*365 -> 56504920 | C14: CP | D14: Exposicion anual del grupo que la Ferropista captaria.
A15: Vehiculos-km anuales evitados con la captacion prevista | B15: =B14*$B$9 -> 50854428 | C15: CP | D15: Aplicando la captacion de la ponencia. Es una estimacion condicionada, no un pronostico.
A16: Diferencia entre puntos de medicion (Cajamarca 2019 - Cocora hoy) | B16: =B6-B7 -> 1205 | C16: CP | D16: Cuanta carga pesada mide de mas el punto alto. NO es una caida temporal: son dos peajes.
A17: Cota superior segun la estacion 244 | B17: =B8 -> 3708 | C17: CP | D17: Incluye camiones de 2 ejes. Sirve de techo, no de valor central.
A19: QUE PUEDE AFIRMARSE CON ESTA MATRIZ
A20: El volumen de carga pesada del corredor esta MEDIDO en peaje, no supuesto, en dos puntos y dos periodos.
A21: La exposicion anual en vehiculos-kilometro de ese grupo es calculable y reproducible.
A23: QUE NO PUEDE AFIRMARSE
A24: Que la carga pesada haya caido entre 2019 y hoy: los dos numeros vienen de peajes distintos, separados 10 km,
A25: y el de abajo capta trafico local. Homologar los puntos de medicion es requisito antes de cualquier serie unica.
A26: Cuantos vehiculos dejarian de subir: la captacion del 90 % es cifra del proponente y entra como hipotesis.
